Workbook

Sheet Main
E2: Time last checked | F2: Today | G2: Earnings
B3: 7267 | C3: Price | D3: 33.54 | E3: 45904 | F3: =TODAY() -> 45904 | G3: 45966
C4: Shares | D4: =4346.5/3 -> 1448.8333 | E4: Q425
C5: MC | D5: =D3*D4 -> 48593.87
C6: Cash JPY | D6: =4528795+1242614 -> 5771409 | E6: Q425
C7: Debt JPY | D7: =4497747+6953520 -> 11451267 | E7: Q425
C8: Cash USD | D8: =D6/$D$13 -> 38893.517 | E8: Q425
C9: Debt USD | D9: =D7/$D$13 -> 77170.072 | E9: Q425
C10: Net Cash | D10: =D8-D9 -> -38276.555 | E10: Q425
C11: EV | D11: =D5-D10 -> 86870.425
C13: USD/JPY | D13: 148.39

Sheet Model
C1: 43190 | D1: 43555 | E1: 43921 | F1: 44286 | G1: 44651 | H1: 45016 | I1: 45382 | J1: 45747 | K1: 46112 | L1: 46477 | M1: 46843 | N1: 47208 | O1: 47573 | P1: 47938 | Q1: 48304 | R1: 48669 | S1: 49034 | T1: 49399
C2: 2018 | D2: 2019 | E2: 2020 | F2: 2021 | G2: 2022 | H2: 2023 | I2: 2024 | J2: 2025 | K2: 2026 | L2: 2027 | M2: 2028 | N2: 2029 | O2: 2030 | P2: 2031 | Q2: 2032 | R2: 2033 | S2: 2034 | T2: 2035
B3: Revenue | C3: =C30/Main!$D$13 -> 103518.74 | D3: =D30/Main!$D$13 -> 107073.37 | E3: =E30/Main!$D$13 -> 100620.05 | F3: =F30/Main!$D$13 -> 88756.109 | G3: =G30/Main!$D$13 -> 98070.598 | H3: =H30/Main!$D$13 -> 113941.13 | I3: =I30/Main!$D$13 -> 137669.67 | J3: =J30/Main!$D$13 -> 146160.57 | K3: =J3*1.03 -> 150545.39 | L3: =K3*1.02 -> 153556.29 | M3: =L3*1.01 -> 155091.86 | N3: =M3*1.01 -> 156642.78 | O3: =N3*1.01 -> 158209.2 | P3: =O3*1.01 -> 159791.3 | Q3: =P3*1.01 -> 161389.21 | R3: =Q3*1.01 -> 163003.1 | S3: =R3*1.01 -> 164633.13 | T3: =S3*1.01 -> 166279.46
B4: Cost of sales | C4: =C31/Main!$D$13 -> 80871.898 | D4: =D31/Main!$D$13 -> 84782.998 | E4: =E31/Main!$D$13 -> 79868.313 | F4: =F31/Main!$D$13 -> 70353.049 | G4: =G31/Main!$D$13 -> 77956.217 | H4: =H31/Main!$D$13 -> 91489.541 | I4: =I31/Main!$D$13 -> 107936.24 | J4: =J31/Main!$D$13 -> 114730.02 | K4: =K3-K5 -> 118930.86 | L4: =L3-L5 -> 121309.47 | M4: =M3-M5 -> 122522.57 | N4: =N3-N5 -> 123747.79 | O4: =O3-O5 -> 124985.27 | P4: =P3-P5 -> 126235.12 | Q4: =Q3-Q5 -> 127497.48 | R4: =R3-R5 -> 128772.45 | ... T4: =T3-T5 -> 131360.78
B5: Gross profit | C5: =C3-C4 -> 22646.843 | D5: =D3-D4 -> 22290.37 | E5: =E3-E4 -> 20751.735 | F5: =F3*0.21 -> 18638.783 | G5: =G3*0.21 -> 20594.826 | H5: =H3*0.21 -> 23927.638 | I5: =I3*0.21 -> 28910.63 | J5: =J3*0.21 -> 30693.72 | K5: =K3*0.21 -> 31614.531 | L5: =L3*0.21 -> 32246.822 | M5: =M3*0.21 -> 32569.29 | ... T5: =T3*0.21 -> 34918.687
B6: SG&A | C6: =C33/Main!$D$13 -> 11962.74 | D6: =D33/Main!$D$13 -> 11957.632 | E6: =E33/Main!$D$13 -> 11062.673 | F6: =F33/Main!$D$13 -> 8974.5131 | G6: =G33/Main!$D$13 -> 8939.1805 | H6: =H33/Main!$D$13 -> 11253.508 | I6: =I33/Main!$D$13 -> 14195.963 | J6: =J33/Main!$D$13 -> 15843.46 | K6: =K3*0.11 -> 16559.993 | L6: =L3*0.11 -> 16891.192 | M6: =M3*0.11 -> 17060.104 | N6: =N3*0.11 -> 17230.705 | O6: =O3*0.11 -> 17403.012 | P6: =P3*0.11 -> 17577.043 | Q6: =Q3*0.11 -> 17752.813 | R6: =R3*0.11 -> 17930.341 | ... T6: =T3*0.11 -> 18290.741
B7: R&D | C7: =C34/Main!$D$13 -> 5066.7565 | D7: =D34/Main!$D$13 -> 5437.7317 | E7: =E34/Main!$D$13 -> 5418.9838 | F7: =F34/Main!$D$13 -> 4979.4056 | G7: =G34/Main!$D$13 -> 5303.9693 | H7: =H34/Main!$D$13 -> 5936.4849 | I7: =I34/Main!$D$13 -> 6224.321 | J7: =J34/Main!$D$13 -> 7409.4076 | K7: =J7*1.07 -> 7928.0662 | L7: =K7*1.03 -> 8165.9082 | M7: =L7*1.02 -> 8329.2263 | N7: =M7*1.01 -> 8412.5186 | O7: =N7*1.01 -> 8496.6438 | P7: =O7*1.01 -> 8581.6102 | Q7: =P7*1.01 -> 8667.4263 | R7: =Q7*1.01 -> 8754.1006 | S7: =R7*1.01 -> 8841.6416 | T7: =S7*1.01 -> 8930.058
B8: Operating profit | C8: =C5-C6-C7 -> 5617.3462 | D8: =D5-D6-D7 -> 4895.0064 | E8: =E5-E6-E7 -> 4270.0788 | F8: =F5-F6-F7 -> 4684.8641 | G8: =G5-G6-G7 -> 6351.6757 | H8: =H5-H6-H7 -> 6737.6457 | I8: =I5-I6-I7 -> 8490.3458 | J8: =J5-J6-J7 -> 7440.8523 | ... T8: =T5-T6-T7 -> 7697.8884
B9: Investments | C9: =C36/Main!$D$13 -> -1668.8658 | D9: =D36/Main!$D$13 -> -1542.0648 | E9: =E36/Main!$D$13 -> -1106.5638 | F9: =F36/Main!$D$13 -> -1837.954 | G9: =G36/Main!$D$13 -> -1364.7281 | H9: =H36/Main!$D$13 -> -791.46169 | I9: =I36/Main!$D$13 -> -746.79561 | J9: =J36/Main!$D$13 -> -6.6176966 | K9: =J9*1.05 -> -6.9485814 | L9: =K9*1.05 -> -7.2960105 | M9: =L9*1.05 -> -7.660811 | N9: =M9*1.05 -> -8.0438516 | O9: =N9*1.05 -> -8.4460442 | P9: =O9*1.05 -> -8.8683464 | Q9: =P9*1.05 -> -9.3117637 | R9: =Q9*1.05 -> -9.7773519 | ... T9: =S9*1.05 -> -10.77953
B10: Interest income | C10: =C40/Main!$D$13 -> -227.58946 | D10: =D40/Main!$D$13 -> -162.93551 | E10: =E40/Main!$D$13 -> 53.386347 | F10: =F37/Main!$D$13 -> -133.46587 | G10: =G37/Main!$D$13 -> -172.70032 | H10: =H37/Main!$D$13 -> -492.42537 | I10: =I37/Main!$D$13 -> -1170.5304 | J10: =J37/Main!$D$13 -> -1288.0315 | K10: =J10*1.01 -> -1300.9119 | L10: =K10*1.01 -> -1313.921 | M10: =L10*1.01 -> -1327.0602 | N10: =M10*1.01 -> -1340.3308 | O10: =N10*1.01 -> -1353.7341 | P10: =O10*1.01 -> -1367.2714 | Q10: =P10*1.01 -> -1380.9441 | R10: =Q10*1.01 -> -1394.7536 | ... T10: =S10*1.01 -> -1422.7881
B11: Interest expense | F11: =F38/Main!$D$13 -> 93.517083 | G11: =G38/Main!$D$13 -> 113.66669 | H11: =H38/Main!$D$13 -> 243.35872 | I11: =I38/Main!$D$13 -> 401.85322 | J11: =J38/Main!$D$13 -> 370.0182 | K11: =J11*1.01 -> 373.71838 | L11: =K11*1.01 -> 377.45556 | M11: =L11*1.01 -> 381.23012 | N11: =M11*1.01 -> 385.04242 | O11: =N11*1.01 -> 388.89284 | P11: =O11*1.01 -> 392.78177 | Q11: =P11*1.01 -> 396.70959 | R11: =Q11*1.01 -> 400.67668 | ... T11: =S11*1.01 -> 408.73029
B12: Other income | F12: =F39/Main!$D$13 -> 167.24173 | G12: =G39/Main!$D$13 -> 82.984029 | H12: =H39/Main!$D$13 -> 374.74223 | I12: =I39/Main!$D$13 -> -239.40966 | J12: =J39/Main!$D$13 -> 222.73738 | K12: 0
B13: Net finance expense | F13: =SUM(F9:F12) -> -1710.6611 | G13: =SUM(G9:G12) -> -1340.7777 | H13: =SUM(H9:H12) -> -665.7861 | I13: =SUM(I9:I12) -> -1754.8824 | J13: =SUM(J9:J12) -> -701.89366 | K13: =SUM(K9:K12) -> -934.14206
B14: Pretax income | C14: =C8-C9-C10 -> 7513.8015 | D14: =D8-D9-D10 -> 6600.0067 | E14: =E8-E9-E10 -> 5323.2563 | F14: =F8-F13 -> 6395.5252 | G14: =G8-G13 -> 7692.4534 | H14: =H8-H13 -> 7403.4318 | I14: =I8-I13 -> 10245.228 | J14: =J8-J13 -> 8142.7459 | K14: =K8-K13 -> 8060.6146 | L14: =L8-L9-L10 -> 8510.9383 | M14: =M8-M9-M10 -> 8514.6805 | N14: =N8-N9-N10 -> 8600.1337 | O14: =O8-O9-O10 -> 8686.4568 | P14: =P8-P9-P10 -> 8773.6592 | Q14: =Q8-Q9-Q10 -> 8861.7505 | R14: =R8-R9-R10 -> 8950.7405 | S14: =S8-S9-S10 -> 9040.639 | T14: =T8-T9-T10 -> 9131.456
B15: Taxes | C15: =C42/Main!$D$13 -> -92.095155 | D15: =D42/Main!$D$13 -> 2042.5163 | E15: =E42/Main!$D$13 -> 1886.8253 | F15: =F42/Main!$D$13 -> 1473.2057 | G15: =G42/Main!$D$13 -> 2085.6459 | H15: =H42/Main!$D$13 -> 1093.443 | I15: =I42/Main!$D$13 -> 3098.5511 | J15: =J42/Main!$D$13 -> 2794.0292 | K15: =K14*0.3 -> 2418.1844 | L15: =L14*0.3 -> 2553.2815 | M15: =M14*0.3 -> 2554.4041 | N15: =N14*0.3 -> 2580.0401 | O15: =O14*0.3 -> 2605.937 | P15: =P14*0.3 -> 2632.0978 | Q15: =Q14*0.3 -> 2658.5252 | R15: =R14*0.3 -> 2685.2221 | ... T15: =T14*0.3 -> 2739.4368
B16: Minority interest | C16: =C43/Main!$D$13 -> 467.02608 | D16: =D43/Main!$D$13 -> 444.57174 | E16: =E43/Main!$D$13 -> 365.15938 | F16: =F43/Main!$D$13 -> 256.20999 | G16: =G43/Main!$D$13 -> 361.43945 | H16: =H43/Main!$D$13 -> 444.05283 | I16: =I43/Main!$D$13 -> 508.22832 | J16: =J43/Main!$D$13 -> 452.84049 | K16: =J16*1.01 -> 457.36889 | L16: =K16*1.01 -> 461.94258 | M16: =L16*1.01 -> 466.56201 | N16: =M16*1.01 -> 471.22763 | O16: =N16*1.01 -> 475.9399 | P16: =O16*1.01 -> 480.6993 | Q16: =P16*1.01 -> 485.5063 | R16: =Q16*1.01 -> 490.36136 | ... T16: =S16*1.01 -> 500.21762
B17: Net income | C17: =C14-C15-C16 -> 7138.8705 | D17: =D14-D15-D16 -> 4112.9187 | E17: =E14-E15-E16 -> 3071.2716 | F17: =F14-F15-F16 -> 4666.1095 | G17: =G14-G15-G16 -> 5245.368 | H17: =H14-H15-H16 -> 5865.936 | I17: =I14-I15-I16 -> 6638.4488 | J17: =J14-J15-J16 -> 4895.8762 | ... T17: =T14-T15-T16 -> 5891.8016 | U17: =T17*(1+$W$25) -> 5832.8836 | V17: =U17*(1+$W$25) -> 5774.5548 | W17: =V17*(1+$W$25) -> 5716.8092 | X17: =W17*(1+$W$25) -> 5659.6411 | Y17: =X17*(1+$W$25) -> 5603.0447 | Z17: =Y17*(1+$W$25) -> 5547.0143 | AA17: =Z17*(1+$W$25) -> 5491.5441 | AB17: =AA17*(1+$W$25) -> 5436.6287 | ... DJ17: =DI17*(1+$W$25) -> 2290.6377
B18: Shares | C18: 1727 | D18: 1727 | E18: 1727 | F18: 1727 | G18: 1727 | H18: 1727 | I18: 1727 | J18: 1727 | K18: 1727 | L18: 1727 | M18: 1727 | N18: 1727 | O18: 1727 | P18: 1727 | Q18: 1727 | R18: 1727 | S18: 1727 | T18: 1727
B19: EPS | C19: =C17/C18 -> 4.133683 | D19: =D17/D18 -> 2.3815395 | E19: =E17/E18 -> 1.7783854 | F19: =F17/F18 -> 2.7018584 | G19: =G17/G18 -> 3.0372716 | H19: =H17/H18 -> 3.3966045 | I19: =I17/I18 -> 3.8439194 | J19: =J17/J18 -> 2.8349023 | ... T19: =T17/T18 -> 3.4115817
B21: Gross Margin | C21: =C5/C3 -> 0.21877046 | D21: =D5/D3 -> 0.20817847 | E21: =E5/E3 -> 0.20623857 | F21: =F5/F3 -> 0.21 | G21: =G5/G3 -> 0.21 | H21: =H5/H3 -> 0.21 | I21: =I5/I3 -> 0.21 | J21: =J5/J3 -> 0.21 | ... T21: =T5/T3 -> 0.21
B22: Operating Margin | C22: =C8/C3 -> 0.05426405 | D22: =D8/D3 -> 0.045716377 | E22: =E8/E3 -> 0.042437654 | F22: =F8/F3 -> 0.052783568 | G22: =G8/G3 -> 0.064766361 | H22: =H8/H3 -> 0.059132689 | I22: =I8/I3 -> 0.06167187 | J22: =J8/J3 -> 0.050908752 | ... T22: =T8/T3 -> 0.046294883
B23: SG&A Margin | C23: =C6/C3 -> 0.1155611 | D23: =D6/D3 -> 0.11167699 | E23: =E6/E3 -> 0.10994501 | F23: =F6/F3 -> 0.10111431 | G23: =G6/G3 -> 0.091150464 | H23: =H6/H3 -> 0.098765978 | I23: =I6/I3 -> 0.10311613 | J23: =J6/J3 -> 0.10839763 | ... T23: =T6/T3 -> 0.11
B24: R&D Margin | C24: =C7/C3 -> 0.048945307 | D24: =D7/D3 -> 0.0507851 | E24: =E7/E3 -> 0.053855905 | F24: =F7/F3 -> 0.056102117 | G24: =G7/G3 -> 0.054083175 | H24: =H7/H3 -> 0.052101332 | I24: =I7/I3 -> 0.045212 | J24: =J7/J3 -> 0.050693615 | ... T24: =T7/T3 -> 0.053705117
B25: R&D y/y | D25: =D7/C7-1 -> 0.073217478 | E25: =E7/D7-1 -> -0.0034477417 | F25: =F7/E7-1 -> -0.081118187 | G25: =G7/F7-1 -> 0.065181203 | H25: =H7/G7-1 -> 0.11925327 | I25: =I7/H7-1 -> 0.048485949 | J25: =J7/I7-1 -> 0.19039612 | K25: =K7/J7-1 -> 0.07 | ... T25: =T7/S7-1 -> 0.01 | V25: Maturity | W25: -0.01
B26: Revenue y/y | D26: =D3/C3-1 -> 0.034337998 | E26: =E3/D3-1 -> -0.060270066 | F26: =F3/E3-1 -> -0.11790831 | G26: =G3/F3-1 -> 0.10494476 | H26: =H3/G3-1 -> 0.16182768 | I26: =I3/H3-1 -> 0.20825256 | J26: =J3/I3-1 -> 0.061675912 | K26: =K3/J3-1 -> 0.03 | ... T26: =T3/S3-1 -> 0.01 | V26: Discount rate | W26: 0.07
V27: NPV | W27: =NPV(W26,F17:DJ17) -> 76658.886
B28: Taxes | C28: =C15/C14 -> -0.012256799 | D28: =D15/D14 -> 0.30947186 | E28: =E15/E14 -> 0.35444945 | F28: =F15/F14 -> 0.23034945 | G28: =G15/G14 -> 0.27112884 | H28: =H15/H14 -> 0.14769407 | I28: =I15/I14 -> 0.30243847 | J28: =J15/J14 -> 0.34313108 | ... T28: =T15/T14 -> 0.3 | V28: Net cash | W28: =Main!D10 -> -38276.555
V29: Value | W29: =W27+W28 -> 38382.331
B30: Revenue | C30: 15361146 | D30: 15888617 | E30: 14931009 | F30: 13170519 | G30: 14552696 | H30: 16907725 | I30: 20428802 | J30: 21688767 | V30: Per share | W30: =W29/O18 -> 22.224858
B31: Cost of sales | C31: 12000581 | D31: 12580949 | E31: 11851659 | F31: 10439689 | G31: 11567923 | H31: 13576133 | I31: 16016659 | J31: 17024788 | V31: Current price | W31: =Main!D3 -> 33.54
B32: Gross profit | C32: =C30-C31 -> 3360565 | D32: =D30-D31 -> 3307668 | E32: =E30-E31 -> 3079350 | F32: =F30-F31 -> 2730830 | G32: =G30-G31 -> 2984773 | H32: =H30-H31 -> 3331592 | I32: =I30-I31 -> 4412143 | J32: =J30-J31 -> 4663979 | V32: Variance | W32: =W30/W31-1 -> -0.3373626
B33: SG&A | C33: 1775151 | D33: 1774393 | E33: 1641590 | F33: 1331728 | G33: 1326485 | H33: 1669908 | I33: 2106539 | J33: 2351011 | V33: Consensus | W33: Overvalued
B34: R&D | C34: 751856 | D34: 806905 | E34: 804123 | F34: 738894 | G34: 787056 | H34: 880915 | I34: 923627 | J34: 1099482
B35: Operating profit | C35: =C32-C33-C34 -> 833558 | D35: =D32-D33-D34 -> 726370 | E35: =E32-E33-E34 -> 633637 | F35: =F32-F33-F34 -> 660208 | G35: =G32-G33-G34 -> 871232 | H35: =H32-H33-H34 -> 780769 | I35: =I32-I33-I34 -> 1381977 | J35: =J32-J33-J34 -> 1213486
B36: Investments | C36: -247643 | D36: -228827 | E36: -164203 | F36: -272734 | G36: -202512 | H36: -117445 | I36: -110817 | J36: -982
F37: -19805 | G37: -25627 | H37: -73071 | I37: -173695 | J37: -191131
F38: 13877 | G38: 16867 | H38: 36112 | I38: 59631 | J38: 54907
F39: 24817 | G39: 12314 | H39: 55608 | I39: -35526 | J39: 33052
B40: Net finance expense | C40: -33772 | D40: -24178 | E40: 7922 | F40: =SUM(F36:F39) -> -253845 | G40: =SUM(G36:G39) -> -198958 | H40: =SUM(H36:H39) -> -98796 | I40: =SUM(I36:I39) -> -260407 | J40: =SUM(J36:J39) -> -104154
B41: Pretax income | C41: =C35-C36-C40 -> 1114973 | D41: =D35-D36-D40 -> 979375 | E41: =E35-E36-E40 -> 789918 | F41: =F35-F40 -> 914053 | G41: =G35-G40 -> 1070190 | H41: =H35-H40 -> 879565 | I41: =I35-I40 -> 1642384 | J41: =J35-J40 -> 1317640
...

Sheet Currency
A1: Currency Name | B1: Code | C1: 1 usd | D1: in usd | E1: Converter | F1: Chart
A2: Japanese Yen | B2: JPY | C2: 105.67493 | D2: 0.009463 | E2: USD/JPY
