Workbook

Sheet Main
E2: Last checked | F2: Today | G2: Earnings
B3: CHGG | C3: Price | D3: 0.9801 | E3: 45799 | F3: =TODAY() -> 45799 | G3: 45880
C4: Shares | D4: 106.6 | E4: Q125
C5: MC | D5: =D3*D4 -> 104.47866
C6: Cash | D6: =44.1+44.2+38.1 -> 126.4 | E6: Q125
C7: Debt | D7: =62.5 -> 62.5 | E7: Q125 | J7: Chegg | K7: AI student help
C8: Net Cash | D8: =D6-D7 -> 63.9 | J8: Busuu | K8: Language learning
C9: EV | D9: =D5-D8 -> 40.57866

Sheet Model
P1: Non-GAAP
C2: Q121 | D2: Q221 | E2: Q321 | F2: Q421 | G2: Q122 | H2: Q222 | I2: Q322 | J2: Q422 | K2: Q123 | L2: Q223 | M2: Q323 | N2: Q423 | O2: Q124 | P2: Q224 | Q2: Q324 | R2: Q424 | S2: Q125 | T2: Q225 | U2: Q325 | V2: Q425 | X2: 2018 | Y2: 2019 | Z2: 2020 | AA2: 2021 | AB2: 2022 | AC2: 2023 | AD2: 2024 | AE2: 2025 | AF2: 2026 | AG2: 2027 | AH2: 2028 | AI2: 2029 | AJ2: 2030 | AK2: 2031 | AL2: 2032 | AM2: 2033 | AN2: 2034 | AO2: 2035
B3: Revenue | C3: 198.4 | D3: 198.5 | E3: 171.9 | F3: 207.5 | G3: 202.2 | H3: 194.7 | I3: 164.7 | J3: 205.2 | K3: 187.6 | L3: 182.9 | M3: 157.9 | N3: 188 | O3: 174.4 | P3: 163.1 | Q3: 136.6 | R3: 143.5 | S3: 121.4 | T3: =P3*0.8 -> 130.48 | U3: =Q3*0.75 -> 102.45 | V3: =R3*0.95 -> 136.325 | X3: 321.1 | Y3: 410.9 | Z3: 644.3 | AA3: =SUM(C3:F3) -> 776.3 | AB3: =SUM(G3:J3) -> 766.8 | AC3: =SUM(K3:N3) -> 716.4 | AD3: =SUM(O3:R3) -> 617.6 | AE3: =SUM(S3:V3) -> 490.655 | AF3: =AE3*0.98 -> 480.8419 | AG3: =AF3*1.1 -> 528.92609 | AH3: =AG3*1.07 -> 565.95092 | AI3: =AH3*1.05 -> 594.24846 | AJ3: =AI3*1.04 -> 618.0184 | AK3: =AJ3*1.03 -> 636.55895 | AL3: =AK3*1.03 -> 655.65572 | AM3: =AL3*1.03 -> 675.32539 | AN3: =AM3*1.03 -> 695.58515 | AO3: =AN3*1.03 -> 716.45271
B4: Cost of sales | C4: 71.4 | D4: 60.7 | E4: 67.1 | F4: 55.7 | G4: 55.1 | H4: 45.7 | I4: 45.2 | J4: 51.4 | K4: 49.2 | L4: 47.4 | M4: 83.6 | N4: 45.8 | O4: 46.5 | P4: 45.4 | Q4: 43.4 | R4: 45.6 | S4: 54 | T4: =T3-T5 -> 41.7536 | U4: =U3-U5 -> 32.784 | V4: =V3-V5 -> 43.624 | X4: 80 | Y4: 92.2 | Z4: 205.4 | AA4: =SUM(C4:F4) -> 254.9 | AB4: =SUM(G4:J4) -> 197.4 | AC4: =SUM(K4:N4) -> 226 | AD4: =SUM(O4:R4) -> 180.9 | AE4: =SUM(S4:V4) -> 172.1616 | AF4: =AF3-AF5 -> 149.06099 | AG4: =AG3-AG5 -> 158.67783 | AH4: =AH3-AH5 -> 169.78527 | AI4: =AI3-AI5 -> 178.27454 | AJ4: =AJ3-AJ5 -> 185.40552 | AK4: =AK3-AK5 -> 190.96769 | AL4: =AL3-AL5 -> 196.69672 | AM4: =AM3-AM5 -> 202.59762 | ... AO4: =AO3-AO5 -> 214.93581
B5: Gross profit | C5: =C3-C4 -> 127 | D5: =D3-D4 -> 137.8 | E5: =E3-E4 -> 104.8 | F5: =F3-F4 -> 151.8 | G5: =G3-G4 -> 147.1 | H5: =H3-H4 -> 149 | I5: =I3-I4 -> 119.5 | J5: =J3-J4 -> 153.8 | ... S5: =S3-S4 -> 67.4 | T5: =T3*0.68 -> 88.7264 | U5: =U3*0.68 -> 69.666 | V5: =V3*0.68 -> 92.701 | X5: =X3-X4 -> 241.1 | Y5: =Y3-Y4 -> 318.7 | Z5: =Z3-Z4 -> 438.9 | AA5: =AA3-AA4 -> 521.4 | AB5: =AB3-AB4 -> 569.4 | AC5: =AC3-AC4 -> 490.4 | AD5: =AD3-AD4 -> 436.7 | AE5: =AE3-AE4 -> 318.4934 | AF5: =AF3*0.69 -> 331.78091 | AG5: =AG3*0.7 -> 370.24826 | AH5: =AH3*0.7 -> 396.16564 | AI5: =AI3*0.7 -> 415.97392 | AJ5: =AJ3*0.7 -> 432.61288 | AK5: =AK3*0.7 -> 445.59127 | AL5: =AL3*0.7 -> 458.959 | AM5: =AM3*0.7 -> 472.72777 | AN5: =AN3*0.7 -> 486.90961 | AO5: =AO3*0.7 -> 501.5169
B6: R&D | C6: 46.1 | D6: 41.6 | E6: 43.3 | F6: 47.8 | G6: 52.4 | H6: 52.5 | I6: 45.4 | J6: 46.3 | K6: 46.9 | L6: 52.9 | M6: 46.2 | N6: 45.7 | O6: 44.4 | P6: 43.7 | Q6: 41.3 | R6: 41 | S6: 29.4 | T6: =P6*0.9 -> 39.33 | U6: =Q6*0.9 -> 37.17 | V6: =R6*0.9 -> 36.9 | X6: 114.3 | Y6: 139.8 | Z6: 170.9 | AA6: =SUM(C6:F6) -> 178.8 | AB6: =SUM(G6:J6) -> 196.6 | AC6: =SUM(K6:N6) -> 191.7 | AD6: =SUM(O6:R6) -> 170.4 | AE6: =SUM(S6:V6) -> 142.8 | AF6: =AE6*1.02 -> 145.656 | AG6: =AF6*1.02 -> 148.56912 | AH6: =AG6*1.02 -> 151.5405 | AI6: =AH6*1.02 -> 154.57131 | AJ6: =AI6*1.02 -> 157.66274 | AK6: =AJ6*1.01 -> 159.23937 | AL6: =AK6*1.01 -> 160.83176 | AM6: =AL6*1.01 -> 162.44008 | AN6: =AM6*1.01 -> 164.06448 | AO6: =AN6*1.01 -> 165.70512
B7: S&M | C7: 26.2 | D7: 21.7 | E7: 27.2 | F7: 30.3 | G7: 42.5 | H7: 35.3 | I7: 31.8 | J7: 38.1 | K7: 37 | L7: 31 | M7: 28.9 | N7: 29.7 | O7: 30.4 | P7: 23.5 | Q7: 26.5 | R7: 27.9 | S7: 25.6 | T7: =T3*0.17 -> 22.1816 | U7: =U3*0.2 -> 20.49 | V7: =V3*0.2 -> 27.265 | X7: 54.7 | Y7: 63.6 | Z7: 81.9 | AA7: =SUM(C7:F7) -> 105.4 | AB7: =SUM(G7:J7) -> 147.7 | AC7: =SUM(K7:N7) -> 126.6 | AD7: =SUM(O7:R7) -> 108.3 | AE7: =SUM(S7:V7) -> 95.5366 | AF7: =AF3*0.17 -> 81.743123 | AG7: =AG3*0.16 -> 84.628174 | AH7: =AH3*0.15 -> 84.892637 | AI7: =AI3*0.15 -> 89.137269 | AJ7: =AJ3*0.15 -> 92.70276 | AK7: =AK3*0.15 -> 95.483843 | AL7: =AL3*0.15 -> 98.348358 | AM7: =AM3*0.15 -> 101.29881 | AN7: =AN3*0.15 -> 104.33777 | AO7: =AO3*0.15 -> 107.46791
B8: G&A | C8: 37.9 | D8: 39.7 | E8: 34 | F8: 47.5 | G8: 46.9 | H8: 53.9 | I8: 53.7 | J8: 61.7 | K8: 59 | L8: 70.3 | M8: 57.1 | N8: 53.4 | O8: 55.5 | P8: 54 | Q8: 51.9 | R8: 56.3 | S8: 39.4 | T8: =P8*1.02 -> 55.08 | U8: =Q8*1.02 -> 52.938 | V8: =R8*1.02 -> 57.426 | X8: 77.7 | Y8: 97.5 | Z8: 129.3 | AA8: =SUM(C8:F8) -> 159.1 | AB8: =SUM(G8:J8) -> 216.2 | AC8: =SUM(K8:N8) -> 239.8 | AD8: =SUM(O8:R8) -> 217.7 | AE8: =SUM(S8:V8) -> 204.844 | AF8: =AE8*1.02 -> 208.94088 | AG8: =AF8*1.02 -> 213.1197 | AH8: =AG8*1.02 -> 217.38209 | AI8: =AH8*1.02 -> 221.72973 | AJ8: =AI8*1.02 -> 226.16433 | AK8: =AJ8*1.02 -> 230.68761 | AL8: =AK8*1.02 -> 235.30137 | AM8: =AL8*1.02 -> 240.00739 | ... AO8: =AN8*1.02 -> 249.70369
B9: Impairment | S9: 2 | AE9: =SUM(S9:V9) -> 2
B10: Total operating expenses | C10: =SUM(C6:C8) -> 110.2 | D10: =SUM(D6:D8) -> 103 | E10: =SUM(E6:E8) -> 104.5 | F10: =SUM(F6:F8) -> 125.6 | G10: =SUM(G6:G8) -> 141.8 | H10: =SUM(H6:H8) -> 141.7 | I10: =SUM(I6:I8) -> 130.9 | J10: =SUM(J6:J8) -> 146.1 | ... R10: =SUM(R6:R8) -> 125.2 | S10: =SUM(S6:S9) -> 96.4 | T10: =SUM(T6:T9) -> 116.5916 | U10: =SUM(U6:U9) -> 110.598 | V10: =SUM(V6:V9) -> 121.591 | X10: =SUM(X6:X8) -> 246.7 | Y10: =SUM(Y6:Y8) -> 300.9 | Z10: =SUM(Z6:Z8) -> 382.1 | AA10: =SUM(AA6:AA8) -> 443.3 | AB10: =SUM(AB6:AB8) -> 560.5 | AC10: =SUM(AC6:AC8) -> 558.1 | AD10: =SUM(AD6:AD8) -> 496.4 | AE10: =SUM(AE6:AE9) -> 445.1806 | AF10: =SUM(AF6:AF9) -> 436.34 | AG10: =SUM(AG6:AG9) -> 446.31699 | AH10: =SUM(AH6:AH9) -> 453.81523 | AI10: =SUM(AI6:AI9) -> 465.43832 | AJ10: =SUM(AJ6:AJ9) -> 476.52983 | AK10: =SUM(AK6:AK9) -> 485.41082 | AL10: =SUM(AL6:AL9) -> 494.48148 | ... AO10: =SUM(AO6:AO9) -> 522.87672
B11: Operating profit | C11: =C5-C10 -> 16.8 | D11: =D5-D10 -> 34.8 | E11: =E5-E10 -> 0.3 | F11: =F5-F10 -> 26.2 | G11: =G5-G10 -> 5.3 | H11: =H5-H10 -> 7.3 | I11: =I5-I10 -> -11.4 | J11: =J5-J10 -> 7.7 | ... V11: =V5-V10 -> -28.89 | X11: =X5-X10 -> -5.6 | Y11: =Y5-Y10 -> 17.8 | Z11: =Z5-Z10 -> 56.8 | AA11: =AA5-AA10 -> 78.1 | AB11: =AB5-AB10 -> 8.9 | AC11: =AC5-AC10 -> -67.7 | AD11: =AD5-AD10 -> -59.7 | AE11: =AE5-AE10 -> -126.6872 | ... AO11: =AO5-AO10 -> -21.359826
B12: Net interest expense | C12: 1.9 | D12: 1.7 | E12: 1.6 | F12: 1.6 | G12: 1.6 | H12: 1.6 | I12: 1.5 | J12: 1.3 | K12: 1.3 | L12: 1.1 | M12: 0.7 | N12: 0.7 | O12: 0.7 | P12: 0.7 | Q12: 0.7 | R12: 0.6 | S12: 0.5 | T12: 1 | U12: 1 | V12: 1 | X12: 11.2 | Y12: 44.9 | Z12: 66.3 | AA12: =SUM(C12:F12) -> 6.8 | AB12: =SUM(G12:J12) -> 6 | AC12: =SUM(K12:N12) -> 3.8 | AD12: =SUM(O12:R12) -> 2.7 | AE12: =SUM(S12:V12) -> 3.5 | AF12: =AE12*1.03 -> 3.605 | AG12: =AF12*1.03 -> 3.71315 | AH12: =AG12*1.03 -> 3.8245445 | AI12: =AH12*1.03 -> 3.9392808 | AJ12: =AI12*1.03 -> 4.0574593 | AK12: =AJ12*1.03 -> 4.179183 | AL12: =AK12*1.03 -> 4.3045585 | AM12: =AL12*1.03 -> 4.4336953 | ... AO12: =AN12*1.03 -> 4.7037073
B13: Other income | C13: 77.2 | D13: -1.9 | E13: -8.7 | F13: -1.1 | G13: -6.2 | H13: -1.8 | I13: -97.3 | J13: 4.2 | K13: -12.1 | L13: -64.1 | M13: -40.5 | N13: -5.1 | O13: -10.8 | P13: -7.1 | Q13: -7.6 | R13: -25.8 | S13: -13 | T13: =P13*1.02 -> -7.242 | U13: =Q13*1.02 -> -7.752 | V13: =R13*1.02 -> -26.316 | X13: -4 | Y13: -20.1 | Z13: -8.7 | AA13: =SUM(C13:F13) -> 65.5 | AB13: =SUM(G13:J13) -> -101.1 | AC13: =SUM(K13:N13) -> -121.8 | AD13: =SUM(O13:R13) -> -51.3 | AE13: =SUM(S13:V13) -> -54.31 | AF13: =AE13*1.03 -> -55.9393 | AG13: =AF13*1.03 -> -57.617479 | AH13: =AG13*1.03 -> -59.346003 | AI13: =AH13*1.03 -> -61.126383 | AJ13: =AI13*1.03 -> -62.960175 | AK13: =AJ13*1.03 -> -64.84898 | AL13: =AK13*1.03 -> -66.79445 | AM13: =AL13*1.03 -> -68.798283 | ... AO13: =AN13*1.03 -> -72.988099
B14: Pretax profit | C14: =C11-C12-C13 -> -62.3 | D14: =D11-D12-D13 -> 35 | E14: =E11-E12-E13 -> 7.4 | F14: =F11-F12-F13 -> 25.7 | G14: =G11-G12-G13 -> 9.9 | H14: =H11-H12-H13 -> 7.5 | I14: =I11-I12-I13 -> 84.4 | J14: =J11-J12-J13 -> 2.2 | ... V14: =V11-V12-V13 -> -3.574 | X14: =X11-X12-X13 -> -12.8 | Y14: =Y11-Y12-Y13 -> -7 | Z14: =Z11-Z12-Z13 -> -0.8 | AA14: =AA11-AA12-AA13 -> 5.8 | AB14: =AB11-AB12-AB13 -> 104 | AC14: =AC11-AC12-AC13 -> 50.3 | AD14: =AD11-AD12-AD13 -> -11.1 | AE14: =AE11-AE12-AE13 -> -75.8772 | ... AO14: =AO11-AO12-AO13 -> 46.924565
B15: Taxes | C15: 2.8 | D15: 2.2 | E15: 0.7 | F15: 1.4 | G15: 4.2 | H15: 0.1 | I15: -167.3 | J15: 0.3 | K15: 4.2 | L15: 19.7 | M15: 0.2 | N15: 8.1 | O15: 9.1 | P15: =138.3-129.9 -> 8.4 | Q15: -2.7 | R15: 4 | S15: 1 | T15: 0 | U15: 0 | V15: 0 | X15: 1.4 | Y15: 2.6 | Z15: 5.4 | AA15: =SUM(C15:F15) -> 7.1 | AB15: =SUM(G15:J15) -> -162.7 | AC15: =SUM(K15:N15) -> 32.2 | AD15: =SUM(O15:R15) -> 18.8 | AE15: =SUM(S15:V15) -> 1 | AF15: =AF14*0.15 -> -7.8337188 | AG15: =AG14*0.15 -> -3.32466 | AH15: =AH14*0.15 -> -0.31921967 | AI15: =AI14*0.15 -> 1.1584066 | AJ15: =AJ14*0.15 -> 2.2478654 | AK15: =AK14*0.15 -> 3.1275361 | AL15: =AL14*0.15 -> 4.0451117 | AM15: =AM14*0.15 -> 5.0019123 | ... AO15: =AO14*0.15 -> 7.0386848
B16: Net profit | C16: =C14-C15 -> -65.1 | D16: =D14-D15 -> 32.8 | E16: =E14-E15 -> 6.7 | F16: =F14-F15 -> 24.3 | G16: =G14-G15 -> 5.7 | H16: =H14-H15 -> 7.4 | I16: =I14-I15 -> 251.7 | J16: =J14-J15 -> 1.9 | ... V16: =V14-V15 -> -3.574 | X16: =X14-X15 -> -14.2 | Y16: =Y14-Y15 -> -9.6 | Z16: =Z14-Z15 -> -6.2 | AA16: =AA14-AA15 -> -1.3 | AB16: =AB14-AB15 -> 266.7 | AC16: =AC14-AC15 -> 18.1 | AD16: =AD14-AD15 -> -29.9 | AE16: =AE14-AE15 -> -76.8772 | ... AO16: =AO14-AO15 -> 39.885881 | AP16: =AO16*(1+$AS$21) -> 39.487022 | AQ16: =AP16*(1+$AS$21) -> 39.092152 | AR16: =AQ16*(1+$AS$21) -> 38.70123 | AS16: =AR16*(1+$AS$21) -> 38.314218 | AT16: =AS16*(1+$AS$21) -> 37.931076 | AU16: =AT16*(1+$AS$21) -> 37.551765 | AV16: =AU16*(1+$AS$21) -> 37.176247 | AW16: =AV16*(1+$AS$21) -> 36.804485 | ... EO16: =EN16*(1+$AS$21) -> 14.024243
B17: Shares | C17: 103.7 | D17: 103.7 | E17: 103.7 | F17: 103.7 | G17: 103.7 | H17: 103.7 | I17: 103.7 | J17: 103.7 | K17: 103.7 | L17: 103.7 | M17: 103.7 | N17: 103.7 | O17: 103.7 | P17: 103.7 | Q17: 104.3 | R17: 105.1 | S17: 106.6 | T17: 106.6 | U17: 106.6 | V17: 106.6 | X17: 103.7 | Y17: 103.7 | Z17: 103.7 | AA17: 103.7 | AB17: 103.7 | AC17: 103.7 | AD17: 105.1 | AE17: 105.1 | AF17: 105.1 | AG17: 105.1 | AH17: 105.1 | AI17: 105.1 | AJ17: 105.1 | AK17: 105.1 | AL17: 105.1 | AM17: 105.1 | AN17: 105.1 | AO17: 105.1
B18: EPS | C18: =C16/C17 -> -0.62777242 | D18: =D16/D17 -> 0.31629701 | E18: =E16/E17 -> 0.06460945 | F18: =F16/F17 -> 0.2343298 | G18: =G16/G17 -> 0.054966249 | H18: =H16/H17 -> 0.071359691 | I18: =I16/I17 -> 2.4271938 | J18: =J16/J17 -> 0.018322083 | ... V18: =V16/V17 -> -0.033527205 | X18: =X16/X17 -> -0.13693346 | Y18: =Y16/Y17 -> -0.092574735 | Z18: =Z16/Z17 -> -0.05978785 | AA18: =AA16/AA17 -> -0.012536162 | AB18: =AB16/AB17 -> 2.5718419 | AC18: =AC16/AC17 -> 0.17454195 | AD18: =AD16/AD17 -> -0.28449096 | AE18: =AE16/AE17 -> -0.73146717 | ... AO18: =AO16/AO17 -> 0.3795041
B20: Revenue y/y | G20: =G3/C3-1 -> 0.019153226 | H20: =H3/D3-1 -> -0.019143577 | I20: =I3/E3-1 -> -0.041884817 | J20: =J3/F3-1 -> -0.011084337 | K20: =K3/G3-1 -> -0.072205737 | L20: =L3/H3-1 -> -0.060606061 | M20: =M3/I3-1 -> -0.041287189 | N20: =N3/J3-1 -> -0.083820663 | ... V20: =V3/R3-1 -> -0.05 | Y20: =Y3/X3-1 -> 0.27966366 | Z20: =Z3/Y3-1 -> 0.56802142 | AA20: =AA3/Z3-1 -> 0.20487351 | AB20: =AB3/AA3-1 -> -0.012237537 | AC20: =AC3/AB3-1 -> -0.0657277 | AD20: =AD3/AC3-1 -> -0.13791178 | AE20: =AE3/AD3-1 -> -0.20554566 | AF20: =AF3/AE3-1 -> -0.02 | ... AO20: =AO3/AN3-1 -> 0.03
B21: Gross Margin | C21: =C5/C3 -> 0.64012097 | D21: =D5/D3 -> 0.69420655 | E21: =E5/E3 -> 0.60965678 | F21: =F5/F3 -> 0.73156627 | G21: =G5/G3 -> 0.72749753 | H21: =H5/H3 -> 0.76527992 | I21: =I5/I3 -> 0.72556163 | J21: =J5/J3 -> 0.74951267 | ... V21: =V5/V3 -> 0.68 | X21: =X5/X3 -> 0.75085643 | Y21: =Y5/Y3 -> 0.7756145 | Z21: =Z5/Z3 -> 0.68120441 | AA21: =AA5/AA3 -> 0.67164756 | AB21: =AB5/AB3 -> 0.74256651 | AC21: =AC5/AC3 -> 0.68453378 | AD21: =AD5/AD3 -> 0.70709197 | AE21: =AE5/AE3 -> 0.64911883 | ... AO21: =AO5/AO3 -> 0.7 | AR21: Maturity | AS21: -0.01
B22: R&D y/y | G22: =G6/C6-1 -> 0.13665944 | H22: =H6/D6-1 -> 0.26201923 | I22: =I6/E6-1 -> 0.048498845 | J22: =J6/F6-1 -> -0.031380753 | K22: =K6/G6-1 -> -0.10496183 | L22: =L6/H6-1 -> 0.0076190476 | M22: =M6/I6-1 -> 0.017621145 | N22: =N6/J6-1 -> -0.012958963 | ... V22: =V6/R6-1 -> -0.1 | Y22: =Y6/X6-1 -> 0.22309711 | Z22: =Z6/Y6-1 -> 0.22246066 | AA22: =AA6/Z6-1 -> 0.046225863 | AB22: =AB6/AA6-1 -> 0.099552573 | AC22: =AC6/AB6-1 -> -0.024923703 | AD22: =AD6/AC6-1 -> -0.11111111 | AE22: =AE6/AD6-1 -> -0.16197183 | AF22: =AF6/AE6-1 -> 0.02 | ... AO22: =AO6/AN6-1 -> 0.01 | AR22: Discount rate | AS22: 0.12
B23: S&M Margin | C23: =C7/C3 -> 0.13205645 | D23: =D7/D3 -> 0.1093199 | E23: =E7/E3 -> 0.15823153 | F23: =F7/F3 -> 0.1460241 | G23: =G7/G3 -> 0.21018793 | H23: =H7/H3 -> 0.18130457 | I23: =I7/I3 -> 0.19307832 | J23: =J7/J3 -> 0.18567251 | ... V23: =V7/V3 -> 0.2 | X23: =X7/X3 -> 0.17035192 | Y23: =Y7/Y3 -> 0.15478219 | Z23: =Z7/Z3 -> 0.1271147 | AA23: =AA7/AA3 -> 0.13577225 | AB23: =AB7/AB3 -> 0.19261868 | AC23: =AC7/AC3 -> 0.17671692 | AD23: =AD7/AD3 -> 0.17535622 | AE23: =AE7/AE3 -> 0.19471237 | ... AO23: =AO7/AO3 -> 0.15 | AR23: NPV | AS23: =NPV(AS22,AE16:EO16) -> 28.817785
B24: G&A y/y | G24: =G8/C8-1 -> 0.23746702 | H24: =H8/D8-1 -> 0.35768262 | I24: =I8/E8-1 -> 0.57941176 | J24: =J8/F8-1 -> 0.29894737 | K24: =K8/G8-1 -> 0.25799574 | L24: =L8/H8-1 -> 0.30426716 | M24: =M8/I8-1 -> 0.063314711 | N24: =N8/J8-1 -> -0.13452188 | ... V24: =V8/R8-1 -> 0.02 | Y24: =Y8/X8-1 -> 0.25482625 | Z24: =Z8/Y8-1 -> 0.32615385 | AA24: =AA8/Z8-1 -> 0.23047177 | AB24: =AB8/AA8-1 -> 0.35889378 | AC24: =AC8/AB8-1 -> 0.10915819 | AD24: =AD8/AC8-1 -> -0.092160133 | AE24: =AE8/AD8-1 -> -0.059053744 | AF24: =AF8/AE8-1 -> 0.02 | ... AO24: =AO8/AN8-1 -> 0.02 | AR24: Net cash | AS24: =Main!D8 -> 63.9
B25: Operating Margin | C25: =C11/C3 -> 0.084677419 | D25: =D11/D3 -> 0.17531486 | E25: =E11/E3 -> 0.0017452007 | F25: =F11/F3 -> 0.12626506 | G25: =G11/G3 -> 0.026211672 | H25: =H11/H3 -> 0.03749358 | I25: =I11/I3 -> -0.069216758 | J25: =J11/J3 -> 0.037524366 | ... V25: =V11/V3 -> -0.21192004 | X25: =X11/X3 -> -0.01744005 | Y25: =Y11/Y3 -> 0.043319542 | Z25: =Z11/Z3 -> 0.088157691 | AA25: =AA11/AA3 -> 0.10060544 | AB25: =AB11/AB3 -> 0.011606677 | AC25: =AC11/AC3 -> -0.094500279 | AD25: =AD11/AD3 -> -0.096664508 | AE25: =AE11/AE3 -> -0.25820016 | ... AO25: =AO11/AO3 -> -0.029813309 | AR25: Value | AS25: =AS23+AS24 -> 92.717785
B26: Taxes | C26: =C15/C14 -> -0.04494382 | D26: =D15/D14 -> 0.062857143 | E26: =E15/E14 -> 0.094594595 | F26: =F15/F14 -> 0.054474708 | G26: =G15/G14 -> 0.42424242 | H26: =H15/H14 -> 0.013333333 | I26: =I15/I14 -> -1.9822275 | J26: =J15/J14 -> 0.13636364 | ... V26: =V15/V14 -> 0 | X26: =X15/X14 -> -0.109375 | Y26: =Y15/Y14 -> -0.37142857 | Z26: =Z15/Z14 -> -6.75 | AA26: =AA15/AA14 -> 1.2241379 | AB26: =AB15/AB14 -> -1.5644231 | AC26: =AC15/AC14 -> 0.64015905 | AD26: =AD15/AD14 -> -1.6936937 | AE26: =AE15/AE14 -> -0.01317919 | ... AO26: =AO15/AO14 -> 0.15 | AR26: Per share | AS26: =AS25/AO17 -> 0.88218635
B27: Net Margin | C27: =C16/C3 -> -0.328125 | D27: =D16/D3 -> 0.16523929 | E27: =E16/E3 -> 0.038976149 | F27: =F16/F3 -> 0.11710843 | G27: =G16/G3 -> 0.028189911 | H27: =H16/H3 -> 0.038007191 | I27: =I16/I3 -> 1.5282332 | J27: =J16/J3 -> 0.0092592593 | ... V27: =V16/V3 -> -0.026216761 | X27: =X16/X3 -> -0.044222983 | Y27: =Y16/Y3 -> -0.023363349 | Z27: =Z16/Z3 -> -0.0096228465 | AA27: =AA16/AA3 -> -0.0016746103 | AB27: =AB16/AB3 -> 0.34780908 | AC27: =AC16/AC3 -> 0.025265215 | AD27: =AD16/AD3 -> -0.048413212 | AE27: =AE16/AE3 -> -0.1566828 | ... AO27: =AO16/AO3 -> 0.055671338 | AR27: Current price | AS27: =Main!D3 -> 0.9801
AR28: Variance | AS28: =AS26/AS27-1 -> -0.099901698
AR29: Consensus | AS29: Slightly overvalued
B30: Net income | AB30: =AB16 -> 266.7 | AC30: =AC16 -> 18.1 | AD30: -837.1 | AE30: =AE16 -> -76.8772 | AF30: =AF16 -> -44.391073 | AG30: =AG16 -> -18.83974 | AH30: =AH16 -> -1.8089114 | AI30: =AI16 -> 6.5643043 | AJ30: =AJ16 -> 12.737904 | AK30: =AK16 -> 17.722704 | AL30: =AL16 -> 22.922299 | ... AO30: =AO16 -> 39.885881
B31: SBC | AB31: 133.5 | AC31: 133.5 | AD31: 84.6 | AE31: 60 | AF31: =AE31*0.8 -> 48 | AG31: =AF31*0.8 -> 38.4 | AH31: =AG31*0.8 -> 30.72 | AI31: =AH31*0.8 -> 24.576 | AJ31: =AI31*0.8 -> 19.6608 | AK31: =AJ31*0.8 -> 15.72864 | AL31: =AK31*0.8 -> 12.582912 | AM31: =AL31*0.8 -> 10.06633 | ... AO31: =AN31*0.8 -> 6.4424509
B32: D&A | AB32: 90 | AC32: 129.7 | AD32: 78.3 | AE32: 60 | AF32: =AE32*0.97 -> 58.2 | AG32: =AF32*0.97 -> 56.454 | AH32: =AG32*0.97 -> 54.76038 | AI32: =AH32*0.97 -> 53.117569 | AJ32: =AI32*0.97 -> 51.524042 | AK32: =AJ32*0.97 -> 49.97832 | AL32: =AK32*0.97 -> 48.478971 | AM32: =AL32*0.97 -> 47.024602 | ... AO32: =AN32*0.97 -> 44.245448
B33: D/T | AB33: -168.9 | AC33: 26.6 | AD33: 143.3 | AE33: 0 | AF33: 0 | AG33: 0 | AH33: 0 | AI33: 0 | AJ33: 0 | AK33: 0 | AL33: 0 | AM33: 0 | AN33: 0 | AO33: 0
B34: Loss on debt | AB34: -93.5 | AC34: -85.9 | AD34: -19.5 | AE34: 0 | AF34: 0 | AG34: 0 | AH34: 0 | AI34: 0 | AJ34: 0 | AK34: 0 | AL34: 0 | AM34: 0 | AN34: 0 | AO34: 0
B35: Contingencies | AB35: 0 | AC35: 7 | AD35: 0 | AE35: 0 | AF35: 0 | AG35: 0 | AH35: 0 | AI35: 0 | AJ35: 0 | AK35: 0 | AL35: 0 | AM35: 0 | AN35: 0 | AO35: 0
B36: Impairment | AB36: 0 | AC36: 3.6 | AD36: 677.2 | AE36: 0 | AF36: 0 | AG36: 0 | AH36: 0 | AI36: 0 | AJ36: 0 | AK36: 0 | AL36: 0 | AM36: 0 | AN36: 0 | AO36: 0
B37: PP&E | AB37: 3.5 | AC37: 4.1 | AD37: 5.8 | AE37: 5.8 | AF37: 5.8 | AG37: 5.8 | AH37: 5.8 | AI37: 5.8 | AJ37: 5.8 | AK37: 5.8 | AL37: 5.8 | AM37: 5.8 | AN37: 5.8 | AO37: 5.8
B38: Amortisation | AB38: 5.2 | AC38: 3.2 | AD38: 2.1 | AE38: 2.1 | AF38: 2.1 | AG38: 2.1 | AH38: 2.1 | AI38: 2.1 | AJ38: 2.1 | AK38: 2.1 | AL38: 2.1 | AM38: 2.1 | AN38: 2.1 | AO38: 2.1
B39: Leases | AB39: 6.3 | AC39: 6.1 | AD39: 5.9 | AE39: 5.9 | AF39: 5.9 | AG39: 5.9 | AH39: 5.9 | AI39: 5.9 | AJ39: 5.9 | AK39: 5.9 | AL39: 5.9 | AM39: 5.9 | AN39: 5.9 | AO39: 5.9
B40: Loss on investments | AB40: 9.7 | AC40: 2.1 | AD40: 0 | AE40: 0 | AF40: 0 | AG40: 0 | AH40: 0 | AI40: 0 | AJ40: 0 | AK40: 0 | AL40: 0 | AM40: 0 | AN40: 0 | AO40: 0
B41: Gain on investments | AB41: -5 | AC41: 0 | AD41: 0 | AE41: 0 | AF41: 0 | AG41: 0 | AH41: 0 | AI41: 0 | AJ41: 0 | AK41: 0 | AL41: 0 | AM41: 0 | AN41: 0 | AO41: 0
...
