Workbook

Sheet Main
E2: Last checked | F2: Today | G2: Earnings
B3: GE | C3: Price | D3: 329.58 | E3: 46072 | F3: =TODAY() -> 46072 | G3: 46140
C4: Shares | D4: =1048.8 -> 1048.8 | E4: Q425
C5: MC | D5: =D3*D4 -> 345663.5
C6: Cash | D6: =12392+38788 -> 51180 | E6: Q425
C7: Debt | D7: =1686+18808 -> 20494 | E7: Q425
C8: Net Cash | D8: =D6-D7 -> 30686
C9: EV | D9: =D5-D8 -> 314977.5

Sheet Model
C2: Q123 | D2: Q223 | E2: Q323 | F2: Q423 | G2: Q124 | H2: Q224 | I2: Q324 | J2: Q424 | K2: Q125 | L2: Q225 | M2: Q325 | N2: Q425 | O2: Q126 | P2: Q226 | Q2: Q326 | R2: Q426 | U2: 2019 | V2: 2020 | W2: 2021 | X2: 2022 | Y2: 2023 | Z2: 2024 | AA2: 2025 | AB2: 2026 | AC2: 2027 | AD2: 2028 | AE2: 2029 | AF2: 2030 | AG2: 2031 | AH2: 2032 | AI2: 2033 | AJ2: 2034 | AK2: 2035
B3: Commercial (CES) | J3: 7650 | N3: 9468
B4: Defense (DPT) | J4: 2523 | N4: 2839
B5: Total revenue | J5: =SUM(J3:J4) -> 10173 | N5: =SUM(N3:N4) -> 12307
B7: Equipment | G7: 2421 | H7: 2175 | I7: 2448 | J7: =Z7-I7-H7-G7 -> 3230 | K7: 2653 | L7: 2842 | M7: 3163 | N7: 3500 | X7: 7837 | Y7: 9318 | Z7: 10274 | AA7: =SUM(K7:N7) -> 12158 | AB7: =AA7*1.14 -> 13860.12 | AC7: =AB7*1.11 -> 15384.733 | AD7: =AC7*1.08 -> 16615.512 | AE7: =AD7*1.05 -> 17446.287 | AF7: =AE7*1.04 -> 18144.139 | AG7: =AF7*1.03 -> 18688.463 | AH7: =AG7*1.02 -> 19062.232 | AI7: =AH7*1.02 -> 19443.477 | AJ7: =AI7*1.02 -> 19832.347 | AK7: =AJ7*1.02 -> 20228.993
B8: Services | G8: 5655 | H8: 6047 | I8: 6495 | J8: =Z8-I8-H8-G8 -> 6650 | K8: 6347 | L8: 7308 | M8: 8143 | N8: 8365 | X8: 18345 | Y8: 22641 | Z8: 24847 | AA8: =SUM(K8:N8) -> 30163 | AB8: =AA8*1.15 -> 34687.45 | AC8: =AB8*1.13 -> 39196.818 | AD8: =AC8*1.09 -> 42724.532 | AE8: =AD8*1.07 -> 45715.249 | AF8: =AE8*1.04 -> 47543.859 | AG8: =AF8*1.03 -> 48970.175 | AH8: =AG8*1.02 -> 49949.579 | AI8: =AH8*1.02 -> 50948.57 | AJ8: =AI8*1.02 -> 51967.542 | AK8: =AJ8*1.02 -> 53006.892
B9: Insurance | G9: 879 | H9: 871 | I9: 899 | J9: =Z9-I9-H9-G9 -> 932 | K9: 934 | L9: 872 | M9: 875 | N9: 852 | X9: 2957 | Y9: 3389 | Z9: 3581 | AA9: =SUM(K9:N9) -> 3533 | AB9: =AA9*1.04 -> 3674.32 | AC9: =AB9*1.03 -> 3784.5496 | AD9: =AC9*1.02 -> 3860.2406 | AE9: =AD9*1.01 -> 3898.843 | AF9: =AE9*1.01 -> 3937.8314 | AG9: =AF9*1.01 -> 3977.2097 | AH9: =AG9*1.01 -> 4016.9818 | AI9: =AH9*1.01 -> 4057.1517 | AJ9: =AI9*1.01 -> 4097.7232 | AK9: =AJ9*1.01 -> 4138.7004
B10: Revenue | G10: =SUM(G7:G8) -> 8076 | H10: =SUM(H7:H8) -> 8222 | I10: =SUM(I7:I8) -> 8943 | J10: =SUM(J7:J8) -> 9880 | K10: =SUM(K7:K8) -> 9000 | L10: =SUM(L7:L8) -> 10150 | M10: =SUM(M7:M8) -> 11306 | N10: =SUM(N7:N8) -> 11865 | X10: =SUM(X7:X8) -> 26182 | Y10: =SUM(Y7:Y8) -> 31959 | Z10: =SUM(Z7:Z8) -> 35121 | AA10: =SUM(AA7:AA8) -> 42321 | AB10: =SUM(AB7:AB8) -> 48547.57 | AC10: =SUM(AC7:AC8) -> 54581.552 | AD10: =SUM(AD7:AD8) -> 59340.044 | AE10: =SUM(AE7:AE8) -> 63161.537 | ... AK10: =SUM(AK7:AK8) -> 73235.886
B11: Equipment | G11: 2465 | H11: 2302 | I11: 2625 | J11: =Z11-I11-H11-G11 -> 2949 | K11: 2335 | L11: 2754 | M11: 3361 | N11: 3931 | X11: 8151 | Y11: 9900 | Z11: 10341 | AA11: =SUM(K11:N11) -> 12381 | AB11: =AB7*0.99 -> 13721.519 | AC11: =AC7*0.99 -> 15230.886 | AD11: =AD7*0.99 -> 16449.357 | AE11: =AE7*0.99 -> 17271.825 | AF11: =AF7*0.99 -> 17962.698 | AG11: =AG7*0.99 -> 18501.578 | AH11: =AH7*0.99 -> 18871.61 | AI11: =AI7*0.99 -> 19249.042 | ... AK11: =AK7*0.99 -> 20026.704
B12: Services | G12: 3281 | H12: 3273 | I12: 3601 | J12: =Z12-I12-H12-G12 -> 3812 | K12: 3660 | L12: 4092 | M12: 4401 | N12: 4432 | X12: 10836 | Y12: 13039 | Z12: 13967 | AA12: =SUM(K12:N12) -> 16585 | AB12: =AB8*0.54 -> 18731.223 | AC12: =AC8*0.53 -> 20774.314 | AD12: =AD8*0.53 -> 22644.002 | AE12: =AE8*0.53 -> 24229.082 | AF12: =AF8*0.53 -> 25198.245 | AG12: =AG8*0.53 -> 25954.193 | AH12: =AH8*0.53 -> 26473.277 | AI12: =AI8*0.53 -> 27002.742 | AJ12: =AJ8*0.53 -> 27542.797 | AK12: =AK8*0.53 -> 28093.653
B13: Cost of sales | G13: =SUM(G11:G12) -> 5746 | H13: =SUM(H11:H12) -> 5575 | I13: =SUM(I11:I12) -> 6226 | J13: =SUM(J11:J12) -> 6761 | K13: =SUM(K11:K12) -> 5995 | L13: =SUM(L11:L12) -> 6846 | M13: =SUM(M11:M12) -> 7762 | N13: =SUM(N11:N12) -> 8363 | X13: =SUM(X11:X12) -> 18987 | Y13: =SUM(Y11:Y12) -> 22939 | Z13: =SUM(Z11:Z12) -> 24308 | AA13: =SUM(AA11:AA12) -> 28966 | AB13: =SUM(AB11:AB12) -> 32452.742 | AC13: =SUM(AC11:AC12) -> 36005.2 | AD13: =SUM(AD11:AD12) -> 39093.359 | AE13: =SUM(AE11:AE12) -> 41500.907 | ... AK13: =SUM(AK11:AK12) -> 48120.357
B14: Gross profit | G14: =G10-G13 -> 2330 | H14: =H10-H13 -> 2647 | I14: =I10-I13 -> 2717 | J14: =J10-J13 -> 3119 | K14: =K10-K13 -> 3005 | L14: =L10-L13 -> 3304 | M14: =M10-M13 -> 3544 | N14: =N10-N13 -> 3502 | X14: =X10-X13 -> 7195 | Y14: =Y10-Y13 -> 9020 | Z14: =Z10-Z13 -> 10813 | AA14: =AA10-AA13 -> 13355 | AB14: =AB10-AB13 -> 16094.828 | AC14: =AC10-AC13 -> 18576.352 | AD14: =AD10-AD13 -> 20246.685 | AE14: =AE10-AE13 -> 21660.63 | ... AK14: =AK10-AK13 -> 25115.529
B15: SG&A | G15: 1026 | H15: 924 | I15: 1330 | J15: =Z15-I15-H15-G15 -> 1157 | K15: 876 | L15: 1020 | M15: 1195 | N15: 997 | X15: 3672 | Y15: 4045 | Z15: 4437 | AA15: =SUM(K15:N15) -> 4088 | AB15: =AA15*1.03 -> 4210.64 | AC15: =AB15*1.02 -> 4294.8528 | AD15: =AC15*1.02 -> 4380.7499 | AE15: =AD15*1.02 -> 4468.3649 | AF15: =AE15*1.02 -> 4557.7322 | AG15: =AF15*1.02 -> 4648.8868 | AH15: =AG15*1.02 -> 4741.8645 | AI15: =AH15*1.02 -> 4836.7018 | AJ15: =AI15*1.02 -> 4933.4359 | AK15: =AJ15*1.02 -> 5032.1046
B16: Restructuring | G16: 259 | H16: 75 | I16: 74 | J16: =Z16-I16-H16-G16 -> 84 | K16: 51 | L16: 47 | M16: 53 | N16: 52 | X16: 625 | Y16: 692 | Z16: 492 | AA16: =SUM(K16:N16) -> 203 | AB16: 0 | AC16: 0 | AD16: 0 | AE16: 0 | AF16: 0 | AG16: 0 | AH16: 0 | AI16: 0 | AJ16: 0 | AK16: 0
B17: R&D | G17: 270 | H17: 300 | I17: 331 | J17: =Z17-I17-H17-G17 -> 385 | K17: 359 | L17: 359 | M17: 415 | N17: 448 | X17: 808 | Y17: 1011 | Z17: 1286 | AA17: =SUM(K17:N17) -> 1581 | AB17: =AA17*1.18 -> 1865.58 | AC17: =AB17*1.12 -> 2089.4496 | AD17: =AC17*1.08 -> 2256.6056 | AE17: =AD17*1.05 -> 2369.4358 | AF17: =AE17*1.03 -> 2440.5189 | AG17: =AF17*1.03 -> 2513.7345 | AH17: =AG17*1.03 -> 2589.1465 | AI17: =AH17*1.03 -> 2666.8209 | AJ17: =AI17*1.03 -> 2746.8255 | AK17: =AJ17*1.03 -> 2829.2303
B18: Finance expense | G18: 263 | H18: 248 | I18: 251 | J18: =Z18-I18-H18-G18 -> 224 | K18: 210 | L18: 158 | M18: 225 | N18: 250 | X18: =1339+465 -> 1804 | Y18: 1029 | Z18: 986 | AA18: =SUM(K18:N18) -> 843 | AB18: =AA18*1.02 -> 859.86 | AC18: =AB18*1.02 -> 877.0572 | AD18: =AC18*1.02 -> 894.59834 | AE18: =AD18*1.02 -> 912.49031 | AF18: =AE18*1.02 -> 930.74012 | AG18: =AF18*1.02 -> 949.35492 | AH18: =AG18*1.02 -> 968.34202 | AI18: =AH18*1.02 -> 987.70886 | ... AK18: =AJ18*1.02 -> 1027.6123
B19: Insurance | G19: 627 | H19: 667 | I19: 714 | J19: =Z19-I19-H19-G19 -> 421 | K19: 701 | L19: 698 | M19: 500 | N19: 550 | X19: 2592 | Y19: 2886 | Z19: 2429 | AA19: =SUM(K19:N19) -> 2449 | AB19: =AA19*1.03 -> 2522.47 | AC19: =AB19*1.02 -> 2572.9194 | AD19: =AC19*1.02 -> 2624.3778 | AE19: =AD19*1.01 -> 2650.6216 | AF19: =AE19*1.01 -> 2677.1278 | AG19: =AF19*1.01 -> 2703.8991 | AH19: =AG19*1.01 -> 2730.938 | AI19: =AH19*1.01 -> 2758.2474 | AJ19: =AI19*1.01 -> 2785.8299 | AK19: =AJ19*1.01 -> 2813.6882
B20: Impairment | G20: 0 | H20: 0 | I20: 251 | J20: =Z20-I20-H20-G20 -> 0 | K20: 0 | L20: 0 | M20: 0 | N20: 0 | X20: 0 | Y20: 0 | Z20: 251 | AA20: =SUM(K20:N20) -> 0 | AB20: 0 | AC20: 0 | AD20: 0 | AE20: 0 | AF20: 0 | AG20: 0 | AH20: 0 | AI20: 0 | AJ20: 0 | AK20: 0
B21: Total opex | G21: =-G9+SUM(G15:G20) -> 1566 | H21: =-H9+SUM(H15:H20) -> 1343 | I21: =-I9+SUM(I15:I20) -> 2052 | J21: =-J9+SUM(J15:J20) -> 1339 | K21: =-K9+SUM(K15:K20) -> 1263 | L21: =-L9+SUM(L15:L20) -> 1410 | M21: =-M9+SUM(M15:M20) -> 1513 | N21: =-N9+SUM(N15:N20) -> 1445 | X21: =-X9+SUM(X15:X20) -> 6544 | Y21: =-Y9+SUM(Y15:Y20) -> 6274 | Z21: =-Z9+SUM(Z15:Z20) -> 6300 | AA21: =-AA9+SUM(AA15:AA20) -> 5631 | AB21: =-AB9+SUM(AB15:AB20) -> 5784.23 | AC21: =-AC9+SUM(AC15:AC20) -> 6049.7294 | AD21: =-AD9+SUM(AD15:AD20) -> 6296.091 | AE21: =-AE9+SUM(AE15:AE20) -> 6502.0696 | ... AK21: =-AK9+SUM(AK15:AK20) -> 7563.935
B22: Operating profit | G22: =G14-G21 -> 764 | H22: =H14-H21 -> 1304 | I22: =I14-I21 -> 665 | J22: =J14-J21 -> 1780 | K22: =K14-K21 -> 1742 | L22: =L14-L21 -> 1894 | M22: =M14-M21 -> 2031 | N22: =N14-N21 -> 2057 | X22: =X14-X21 -> 651 | Y22: =Y14-Y21 -> 2746 | Z22: =Z14-Z21 -> 4513 | AA22: =AA14-AA21 -> 7724 | AB22: =AB14-AB21 -> 10310.598 | AC22: =AC14-AC21 -> 12526.623 | AD22: =AD14-AD21 -> 13950.594 | AE22: =AE14-AE21 -> 15158.561 | ... AK22: =AK14-AK21 -> 17551.594
B23: Other expense | G23: -217 | H23: -204 | I23: -207 | J23: =Z23-I23-H23-G23 -> -214 | K23: -201 | L23: -197 | M23: -198 | N23: -192 | X23: -60 | Y23: -978 | Z23: -842 | AA23: =SUM(K23:N23) -> -788 | AB23: =AA23*1.01 -> -795.88 | AC23: =AB23*1.01 -> -803.8388 | AD23: =AC23*1.01 -> -811.87719 | AE23: =AD23*1.01 -> -819.99596 | AF23: =AE23*1.01 -> -828.19592 | AG23: =AF23*1.01 -> -836.47788 | AH23: =AG23*1.01 -> -844.84266 | AI23: =AH23*1.01 -> -853.29108 | ... AK23: =AJ23*1.01 -> -870.44223
B24: Other income | G24: -1007 | H24: 63 | I24: -1021 | J24: =Z24-I24-H24-G24 -> -299 | K24: -302 | L24: -298 | M24: -285 | N24: -602 | X24: -811 | Y24: -6718 | Z24: -2264 | AA24: =SUM(K24:N24) -> -1487 | AB24: =AA24*1.01 -> -1501.87 | AC24: =AB24*1.01 -> -1516.8887 | AD24: =AC24*1.01 -> -1532.0576 | AE24: =AD24*1.01 -> -1547.3782 | AF24: =AE24*1.01 -> -1562.8519 | AG24: =AF24*1.01 -> -1578.4805 | AH24: =AG24*1.01 -> -1594.2653 | AI24: =AH24*1.01 -> -1610.2079 | ... AK24: =AJ24*1.01 -> -1642.5731
B25: Pretax profit | G25: =G22-G23-G24 -> 1988 | H25: =H22-H23-H24 -> 1445 | I25: =I22-I23-I24 -> 1893 | J25: =J22-J23-J24 -> 2293 | K25: =K22-K23-K24 -> 2245 | L25: =L22-L23-L24 -> 2389 | M25: =M22-M23-M24 -> 2514 | N25: =N22-N23-N24 -> 2851 | X25: =X22-X23-X24 -> 1522 | Y25: =Y22-Y23-Y24 -> 10442 | Z25: =Z22-Z23-Z24 -> 7619 | AA25: =AA22-AA23-AA24 -> 9999 | AB25: =AB22-AB23-AB24 -> 12608.348 | AC25: =AC22-AC23-AC24 -> 14847.35 | AD25: =AD22-AD23-AD24 -> 16294.529 | AE25: =AE22-AE23-AE24 -> 17525.935 | ... AK25: =AK22-AK23-AK24 -> 20064.61
B26: Taxes | G26: 244 | H26: 125 | I26: 198 | J26: =Z26-I26-H26-G26 -> 395 | K26: 283 | L26: 388 | M26: 344 | N26: 390 | X26: 169 | Y26: 994 | Z26: 962 | AA26: =SUM(K26:N26) -> 1405 | AB26: =AB25*0.14 -> 1765.1687 | AC26: =AC25*0.14 -> 2078.629 | AD26: =AD25*0.14 -> 2281.2341 | AE26: =AE25*0.14 -> 2453.6309 | AF26: =AF25*0.14 -> 2554.9742 | AG26: =AG25*0.14 -> 2629.0824 | AH26: =AH25*0.14 -> 2672.9812 | AI26: =AI25*0.14 -> 2717.6008 | ... AK26: =AK25*0.14 -> 2809.0454
B27: MI | G27: =178+27 -> 205 | H27: =54+2 -> 56 | I27: =-147-10 -> -157 | J27: =Z27-I27-H27-G27 -> -2 | K27: =-10-5 -> -15 | L27: =-21-7 -> -28 | M27: =17-3 -> 14 | N27: =-89+10 -> -79 | X27: =949+67 -> 1016 | Y27: =3-37 -> -34 | Z27: =91+11 -> 102 | AA27: =SUM(K27:N27) -> -108 | AB27: =AA27*1.02 -> -110.16 | AC27: =AB27*1.02 -> -112.3632 | AD27: =AC27*1.02 -> -114.61046 | AE27: =AD27*1.02 -> -116.90267 | AF27: =AE27*1.02 -> -119.24073 | AG27: =AF27*1.02 -> -121.62554 | AH27: =AG27*1.02 -> -124.05805 | AI27: =AH27*1.02 -> -126.53921 | ... AK27: =AJ27*1.02 -> -131.6514
B28: Net profit | G28: =G25-G26-G27 -> 1539 | H28: =H25-H26-H27 -> 1264 | I28: =I25-I26-I27 -> 1852 | J28: =J25-J26-J27 -> 1900 | K28: =K25-K26-K27 -> 1977 | L28: =L25-L26-L27 -> 2029 | M28: =M25-M26-M27 -> 2156 | N28: =N25-N26-N27 -> 2540 | X28: =X25-X26-X27 -> 337 | Y28: =Y25-Y26-Y27 -> 9482 | Z28: =Z25-Z26-Z27 -> 6555 | AA28: =AA25-AA26-AA27 -> 8702 | AB28: =AB25-AB26-AB27 -> 10953.339 | AC28: =AC25-AC26-AC27 -> 12881.084 | AD28: =AD25-AD26-AD27 -> 14127.905 | AE28: =AE25-AE26-AE27 -> 15189.206 | ... AK28: =AK25-AK26-AK27 -> 17387.216 | AL28: =AK28*(1+$AN$33) -> 17213.344 | AM28: =AL28*(1+$AN$33) -> 17041.21 | AN28: =AM28*(1+$AN$33) -> 16870.798 | AO28: =AN28*(1+$AN$33) -> 16702.09 | AP28: =AO28*(1+$AN$33) -> 16535.069 | AQ28: =AP28*(1+$AN$33) -> 16369.719 | AR28: =AQ28*(1+$AN$33) -> 16206.021 | AS28: =AR28*(1+$AN$33) -> 16043.961 | ... EK28: =EJ28*(1+$AN$33) -> 6113.5051
B29: Shares | G29: =1054.8 -> 1054.8 | H29: =1054.8 -> 1054.8 | I29: =1054.8 -> 1054.8 | J29: =1054.8 -> 1054.8 | K29: =1054.8 -> 1054.8 | L29: =1054.8 -> 1054.8 | M29: =1054.8 -> 1054.8 | N29: =1048.8 -> 1048.8 | O29: =1048.8 -> 1048.8 | P29: =1048.8 -> 1048.8 | Q29: =1048.8 -> 1048.8 | R29: =1048.8 -> 1048.8 | X29: =1054.8 -> 1054.8 | Y29: =1054.8 -> 1054.8 | Z29: =1054.8 -> 1054.8 | AA29: =1048.8 -> 1048.8 | AB29: =1048.8 -> 1048.8 | AC29: =1048.8 -> 1048.8 | AD29: =1048.8 -> 1048.8 | AE29: =1048.8 -> 1048.8 | AF29: =1048.8 -> 1048.8 | AG29: =1048.8 -> 1048.8 | AH29: =1048.8 -> 1048.8 | ... AK29: =1048.8 -> 1048.8
B30: EPS | G30: =G28/G29 -> 1.4590444 | H30: =H28/H29 -> 1.1983314 | I30: =I28/I29 -> 1.7557831 | J30: =J28/J29 -> 1.8012893 | K30: =K28/K29 -> 1.874289 | L30: =L28/L29 -> 1.9235874 | M30: =M28/M29 -> 2.0439894 | N30: =N28/N29 -> 2.4218154 | X30: =X28/X29 -> 0.31949185 | Y30: =Y28/Y29 -> 8.9893819 | Z30: =Z28/Z29 -> 6.2144482 | AA30: =AA28/AA29 -> 8.2971014 | AB30: =AB28/AB29 -> 10.443688 | AC30: =AC28/AC29 -> 12.281736 | AD30: =AD28/AD29 -> 13.470543 | AE30: =AE28/AE29 -> 14.482462 | ... AK30: =AK28/AK29 -> 16.5782
B32: Equipment y/y | K32: =K7/G7-1 -> 0.09582817 | L32: =L7/H7-1 -> 0.30666667 | M32: =M7/I7-1 -> 0.29207516 | N32: =N7/J7-1 -> 0.083591331 | O32: =O7/K7-1 -> -1 | P32: =P7/L7-1 -> -1 | Q32: =Q7/M7-1 -> -1 | R32: =R7/N7-1 -> -1 | Y32: =Y7/X7-1 -> 0.18897537 | Z32: =Z7/Y7-1 -> 0.10259712 | AA32: =AA7/Z7-1 -> 0.18337551 | AB32: =AB7/AA7-1 -> 0.14 | AC32: =AC7/AB7-1 -> 0.11 | AD32: =AD7/AC7-1 -> 0.08 | AE32: =AE7/AD7-1 -> 0.05 | AF32: =AF7/AE7-1 -> 0.04 | ... AK32: =AK7/AJ7-1 -> 0.02
B33: Services y/y | K33: =K8/G8-1 -> 0.12236958 | L33: =L8/H8-1 -> 0.20853316 | M33: =M8/I8-1 -> 0.25373364 | N33: =N8/J8-1 -> 0.25789474 | O33: =O8/K8-1 -> -1 | P33: =P8/L8-1 -> -1 | Q33: =Q8/M8-1 -> -1 | R33: =R8/N8-1 -> -1 | Y33: =Y8/X8-1 -> 0.23417825 | Z33: =Z8/Y8-1 -> 0.097433859 | AA33: =AA8/Z8-1 -> 0.21394937 | AB33: =AB8/AA8-1 -> 0.15 | AC33: =AC8/AB8-1 -> 0.13 | AD33: =AD8/AC8-1 -> 0.09 | AE33: =AE8/AD8-1 -> 0.07 | AF33: =AF8/AE8-1 -> 0.04 | ... AK33: =AK8/AJ8-1 -> 0.02 | AM33: Maturity | AN33: -0.01
B34: Revenue y/y | K34: =K10/G10-1 -> 0.11441308 | L34: =L10/H10-1 -> 0.23449282 | M34: =M10/I10-1 -> 0.26422901 | N34: =N10/J10-1 -> 0.20091093 | O34: =O10/K10-1 -> -1 | P34: =P10/L10-1 -> -1 | Q34: =Q10/M10-1 -> -1 | R34: =R10/N10-1 -> -1 | Y34: =Y10/X10-1 -> 0.22064777 | Z34: =Z10/Y10-1 -> 0.098939266 | AA34: =AA10/Z10-1 -> 0.20500555 | AB34: =AB10/AA10-1 -> 0.14712719 | AC34: =AC10/AB10-1 -> 0.12429009 | AD34: =AD10/AC10-1 -> 0.087181331 | AE34: =AE10/AD10-1 -> 0.064399899 | AF34: =AF10/AE10-1 -> 0.04 | ... AK34: =AK10/AJ10-1 -> 0.02 | AM34: Discount rate | AN34: 0.06
B35: Equipment Margin | G35: =(G7-G11)/G7 -> -0.018174308 | H35: =(H7-H11)/H7 -> -0.058390805 | I35: =(I7-I11)/I7 -> -0.072303922 | J35: =(J7-J11)/J7 -> 0.086996904 | K35: =(K7-K11)/K7 -> 0.1198643 | L35: =(L7-L11)/L7 -> 0.03096411 | M35: =(M7-M11)/M7 -> -0.062598799 | N35: =(N7-N11)/N7 -> -0.12314286 | ... R35: =(R7-R11)/R7 -> #DIV/0! | X35: =(X7-X11)/X7 -> -0.040066352 | Y35: =(Y7-Y11)/Y7 -> -0.062459755 | Z35: =(Z7-Z11)/Z7 -> -0.0065213159 | AA35: =(AA7-AA11)/AA7 -> -0.018341833 | AB35: =(AB7-AB11)/AB7 -> 0.01 | AC35: =(AC7-AC11)/AC7 -> 0.01 | AD35: =(AD7-AD11)/AD7 -> 0.01 | AE35: =(AE7-AE11)/AE7 -> 0.01 | ... AK35: =(AK7-AK11)/AK7 -> 0.01 | AM35: NPV | AN35: =NPV(AN34,AA28:EK28) -> 241761.67
B36: Services Margin | G36: =(G8-G12)/G8 -> 0.41980548 | H36: =(H8-H12)/H8 -> 0.45873987 | I36: =(I8-I12)/I8 -> 0.44557352 | J36: =(J8-J12)/J8 -> 0.42676692 | K36: =(K8-K12)/K8 -> 0.42334961 | L36: =(L8-L12)/L8 -> 0.44006568 | M36: =(M8-M12)/M8 -> 0.4595358 | N36: =(N8-N12)/N8 -> 0.47017334 | ... R36: =(R8-R12)/R8 -> #DIV/0! | X36: =(X8-X12)/X8 -> 0.40932134 | Y36: =(Y8-Y12)/Y8 -> 0.42409788 | Z36: =(Z8-Z12)/Z8 -> 0.43787982 | AA36: =(AA8-AA12)/AA8 -> 0.45015416 | AB36: =(AB8-AB12)/AB8 -> 0.46 | AC36: =(AC8-AC12)/AC8 -> 0.47 | AD36: =(AD8-AD12)/AD8 -> 0.47 | AE36: =(AE8-AE12)/AE8 -> 0.47 | ... AK36: =(AK8-AK12)/AK8 -> 0.47 | AM36: Net cash | AN36: =Main!D8 -> 30686
B37: Gross Margin | G37: =G14/G10 -> 0.28850916 | H37: =H14/H10 -> 0.32194113 | I37: =I14/I10 -> 0.30381304 | J37: =J14/J10 -> 0.31568826 | K37: =K14/K10 -> 0.33388889 | L37: =L14/L10 -> 0.32551724 | M37: =M14/M10 -> 0.31346188 | N37: =N14/N10 -> 0.29515381 | ... R37: =R14/R10 -> #DIV/0! | X37: =X14/X10 -> 0.27480712 | Y37: =Y14/Y10 -> 0.28223662 | Z37: =Z14/Z10 -> 0.30787848 | AA37: =AA14/AA10 -> 0.31556438 | AB37: =AB14/AB10 -> 0.33152696 | AC37: =AC14/AC10 -> 0.34034122 | AD37: =AD14/AD10 -> 0.34119768 | AE37: =AE14/AE10 -> 0.3429402 | ... AK37: =AK14/AK10 -> 0.3429402 | AM37: Value | AN37: =AN35+AN36 -> 272447.67
B38: SG&A y/y | K38: =K15/G15-1 -> -0.14619883 | L38: =L15/H15-1 -> 0.1038961 | M38: =M15/I15-1 -> -0.10150376 | N38: =N15/J15-1 -> -0.13828868 | O38: =O15/K15-1 -> -1 | P38: =P15/L15-1 -> -1 | Q38: =Q15/M15-1 -> -1 | R38: =R15/N15-1 -> -1 | Y38: =Y15/X15-1 -> 0.10157952 | Z38: =Z15/Y15-1 -> 0.096909765 | AA38: =AA15/Z15-1 -> -0.07865675 | AB38: =AB15/AA15-1 -> 0.03 | AC38: =AC15/AB15-1 -> 0.02 | AD38: =AD15/AC15-1 -> 0.02 | AE38: =AE15/AD15-1 -> 0.02 | AF38: =AF15/AE15-1 -> 0.02 | ... AK38: =AK15/AJ15-1 -> 0.02 | AM38: Per share | AN38: =AN37/AK29 -> 259.77085
B39: R&D y/y | K39: =K17/G17-1 -> 0.32962963 | L39: =L17/H17-1 -> 0.19666667 | M39: =M17/I17-1 -> 0.25377644 | N39: =N17/J17-1 -> 0.16363636 | O39: =O17/K17-1 -> -1 | P39: =P17/L17-1 -> -1 | Q39: =Q17/M17-1 -> -1 | R39: =R17/N17-1 -> -1 | Y39: =Y17/X17-1 -> 0.25123762 | Z39: =Z17/Y17-1 -> 0.27200791 | AA39: =AA17/Z17-1 -> 0.22939347 | AB39: =AB17/AA17-1 -> 0.18 | AC39: =AC17/AB17-1 -> 0.12 | AD39: =AD17/AC17-1 -> 0.08 | AE39: =AE17/AD17-1 -> 0.05 | AF39: =AF17/AE17-1 -> 0.03 | ... AK39: =AK17/AJ17-1 -> 0.03 | AM39: Current price | AN39: =Main!D3 -> 329.58
B40: Insurance Margin | G40: =(G9-G19)/G9 -> 0.28668942 | H40: =(H9-H19)/H9 -> 0.23421355 | I40: =(I9-I19)/I9 -> 0.2057842 | J40: =(J9-J19)/J9 -> 0.54828326 | K40: =(K9-K19)/K9 -> 0.24946467 | L40: =(L9-L19)/L9 -> 0.19954128 | M40: =(M9-M19)/M9 -> 0.42857143 | N40: =(N9-N19)/N9 -> 0.35446009 | ... R40: =(R9-R19)/R9 -> #DIV/0! | X40: =(X9-X19)/X9 -> 0.12343591 | Y40: =(Y9-Y19)/Y9 -> 0.14842136 | Z40: =(Z9-Z19)/Z9 -> 0.32169785 | AA40: =(AA9-AA19)/AA9 -> 0.3068214 | AB40: =(AB9-AB19)/AB9 -> 0.31348658 | AC40: =(AC9-AC19)/AC9 -> 0.32015176 | AD40: =(AD9-AD19)/AD9 -> 0.32015176 | AE40: =(AE9-AE19)/AE9 -> 0.32015176 | ... AK40: =(AK9-AK19)/AK9 -> 0.32015176 | AM40: Variance | AN40: =AN38/AN39-1 -> -0.21181245
B41: Operating Margin | G41: =G22/(G10+G9) -> 0.085315466 | H41: =H22/(H10+H9) -> 0.14340702 | I41: =I22/(I10+I9) -> 0.067567568 | J41: =J22/(J10+J9) -> 0.16463189 | K41: =K22/(K10+K9) -> 0.17535736 | L41: =L22/(L10+L9) -> 0.17183814 | M41: =M22/(M10+M9) -> 0.16673508 | N41: =N22/(N10+N9) -> 0.16175199 | ... R41: =R22/(R10+R9) -> #DIV/0! | X41: =X22/(X10+X9) -> 0.022341192 | Y41: =Y22/(Y10+Y9) -> 0.077684735 | Z41: =Z22/(Z10+Z9) -> 0.11660896 | AA41: =AA22/(AA10+AA9) -> 0.16844768 | AB41: =AB22/(AB10+AB9) -> 0.19743824 | AC41: =AC22/(AC10+AC9) -> 0.21462154 | AD41: =AD22/(AD10+AD9) -> 0.22073626 | AE41: =AE22/(AE10+AE9) -> 0.22604346 | ... AK41: =AK22/(AK10+AK9) -> 0.22683927 | AM41: Consensus | AN41: Slightly overvalued
B42: Taxes | G42: =G26/G25 -> 0.12273642 | H42: =H26/H25 -> 0.08650519 | I42: =I26/I25 -> 0.10459588 | J42: =J26/J25 -> 0.17226341 | K42: =K26/K25 -> 0.12605791 | L42: =L26/L25 -> 0.16241105 | M42: =M26/M25 -> 0.13683373 | N42: =N26/N25 -> 0.13679411 | ... R42: =R26/R25 -> #DIV/0! | X42: =X26/X25 -> 0.11103811 | Y42: =Y26/Y25 -> 0.095192492 | Z42: =Z26/Z25 -> 0.12626329 | AA42: =AA26/AA25 -> 0.14051405 | AB42: =AB26/AB25 -> 0.14 | AC42: =AC26/AC25 -> 0.14 | AD42: =AD26/AD25 -> 0.14 | AE42: =AE26/AE25 -> 0.14 | ... AK42: =AK26/AK25 -> 0.14
B43: Net Margin | G43: =G28/(G10+G9) -> 0.1718593 | H43: =H28/(H10+H9) -> 0.13900803 | I43: =I28/(I10+I9) -> 0.18817314 | J43: =J28/(J10+J9) -> 0.17573067 | K43: =K28/(K10+K9) -> 0.19901349 | L43: =L28/(L10+L9) -> 0.18408637 | M43: =M28/(M10+M9) -> 0.17699696 | N43: =N28/(N10+N9) -> 0.19973264 | ... R43: =R28/(R10+R9) -> #DIV/0! | X43: =X28/(X10+X9) -> 0.011565256 | Y43: =Y28/(Y10+Y9) -> 0.26824714 | Z43: =Z28/(Z10+Z9) -> 0.16937109 | AA43: =AA28/(AA10+AA9) -> 0.18977625 | AB43: =AB28/(AB10+AB9) -> 0.20974613 | AC43: =AC28/(AC10+AC9) -> 0.22069462 | AD43: =AD28/(AD10+AD9) -> 0.2235418 | AE43: =AE28/(AE10+AE9) -> 0.22650045 | ... AK43: =AK28/(AK10+AK9) -> 0.22471481
...
