Workbook

Sheet Main
E2: Last checked | F2: Today | G2: Earnings
B3: RHM | C3: Price | D3: 1744.5 | E3: 45906 | F3: =TODAY() -> 45934 | G3: 45967
C4: Shares | D4: 43.84 | E4: Q225
C5: MC | D5: =D3*D4 -> 76478.88
C6: Cash | D6: =1083+328 -> 1411 | E6: Q225
C7: Debt | D7: =193+1511 -> 1704 | E7: Q225
C8: Net Cash | D8: =D6-D7 -> -293
C9: EV | D9: =D5-D8 -> 76771.88

Sheet Model
C2: Q121 | D2: Q221 | E2: Q321 | F2: Q421 | G2: Q122 | H2: Q222 | I2: Q322 | J2: Q422 | K2: Q123 | L2: Q223 | M2: Q323 | N2: Q423 | O2: Q124 | P2: Q224 | Q2: Q324 | R2: Q424 | S2: Q125 | T2: Q225 | U2: Q325 | V2: Q425 | Y2: 2019 | Z2: 2020 | AA2: 2021 | AB2: 2022 | AC2: 2023 | AD2: 2024 | AE2: 2025 | AF2: 2026 | AG2: 2027 | AH2: 2028 | AI2: 2029 | AJ2: 2030 | AK2: 2031 | AL2: 2032 | AM2: 2033 | AN2: 2034 | AO2: 2035
B3: Booked Business | J3: 3521 | K3: 1230 | L3: =1775-K3 -> 545 | M3: 592 | N3: 3480 | O3: 620 | P3: =1357-O3 -> 737 | Q3: =2119-P3-O3 -> 762 | R3: =2508-Q3-P3-O3 -> 389 | S3: 325 | T3: 664 | AB3: 3521 | AC3: 3480 | AD3: 2508
B4: Frame Nomination | J4: 350 | K4: 370 | L4: =1163-K4 -> 793 | M4: 5877 | N4: 7362 | O4: 0 | P4: =7478-O4 -> 7478 | Q4: =10858-P4-O4 -> 3380 | R4: =11518-Q4-P4-O4 -> 660 | S4: 9348 | T4: 433 | AB4: 350 | AC4: 7362 | AD4: 11518
B5: Frame Utilisation | J5: 0 | K5: 0 | L5: =-638-K5 -> -638 | M5: -1726 | N5: -2804 | O5: -444 | P5: =-2369-O5 -> -1925 | Q5: =-2824-P5-O5 -> -455 | R5: =-3738-Q5-P5-O5 -> -914 | S5: -1995 | T5: -256 | AB5: 0 | AC5: -2804 | AD5: -3738
B6: Order Intake | J6: 5629 | K6: 1504 | L6: 3392 | M6: 2570 | N6: 11843 | O6: 3757 | P6: =8910-O6 -> 5153 | Q6: =11275-P6-O6 -> 2365 | R6: =16554-Q6-P6-O6 -> 5279 | S6: 3361 | T6: 1798 | AB6: 5629 | AC6: 11843 | AD6: 16554
B7: Rheinmetall Nomination | J7: =SUM(J3:J6) -> 9500 | K7: =SUM(K3:K6) -> 3104 | L7: =SUM(L3:L6) -> 4092 | M7: =SUM(M3:M6) -> 7313 | N7: =SUM(N3:N6) -> 19881 | O7: =SUM(O3:O6) -> 3933 | P7: =SUM(P3:P6) -> 11443 | Q7: =SUM(Q3:Q6) -> 6052 | ... T7: =SUM(T3:T6) -> 2639 | AB7: =SUM(AB3:AB6) -> 9500 | AC7: =SUM(AC3:AC6) -> 19881 | AD7: =SUM(AD3:AD6) -> 26842
B8: Nominated Backlog | J8: 8056 | K8: 8741 | L8: 8806 | M8: 8875 | N8: 8381 | O8: 8461 | P8: 7938 | Q8: 8060 | R8: 7712 | S8: 6994 | T8: 7192 | AB8: 8056 | AC8: 8381 | AD8: 7712
B9: Frame Backlog | J9: 3427 | K9: 3750 | L9: 3255 | M9: 8118 | N9: 7931 | O9: 7596 | P9: 13041 | Q9: 15896 | R9: 16533 | S9: 22987 | T9: 23707 | AB9: 3427 | AC9: 7931 | AD9: 16533
B10: Order Backlog | J10: 15089 | K10: 15703 | L10: 17989 | M10: 19751 | N10: 21977 | O10: 24140 | P10: 27661 | Q10: 27950 | R10: 30728 | S10: 32579 | T10: 32266 | AB10: 15089 | AC10: 21977 | AD10: 30728
B11: Total Backlog | J11: 26572 | K11: =SUM(K8:K10) -> 28194 | L11: =SUM(L8:L10) -> 30050 | M11: =SUM(M8:M10) -> 36744 | N11: 38290 | O11: =SUM(O8:O10) -> 40197 | P11: =SUM(P8:P10) -> 48640 | Q11: =SUM(Q8:Q10) -> 51906 | R11: =SUM(R8:R10) -> 54973 | S11: =SUM(S8:S10) -> 62560 | T11: =SUM(T8:T10) -> 63165 | AB11: =SUM(AB8:AB10) -> 26572 | AC11: =SUM(AC8:AC10) -> 38289 | AD11: =SUM(AD8:AD10) -> 54973
B13: Vehicle Systems revenue | C13: 406 | D13: 461 | G13: 395 | H13: 446 | I13: 466 | J13: =AB13-I13-H13-G13 -> 944 | K13: 457 | L13: 545 | M13: 653 | N13: =AC13-M13-L13-K13 -> 922 | O13: 489 | P13: 805 | Q13: 1234 | R13: =AD13-Q13-P13-O13 -> 1241 | S13: 945 | T13: 930 | U13: =Q13*1.2 -> 1480.8 | V13: =R13*1.35 -> 1675.35 | Z13: 1828 | AA13: 1875 | AB13: 2251 | AC13: 2577 | AD13: 3769 | AE13: =SUM(S13:V13) -> 5031.15 | AF13: =AE13*1.22 -> 6138.003 | AG13: =AF13*1.08 -> 6629.0432 | AH13: =AG13*1.05 -> 6960.4954 | AI13: =AH13*1.03 -> 7169.3103 | AJ13: =AI13*1.02 -> 7312.6965 | AK13: =AJ13*1.02 -> 7458.9504 | AL13: =AK13*1.02 -> 7608.1294 | AM13: =AL13*1.02 -> 7760.292 | AN13: =AM13*1.02 -> 7915.4978 | AO13: =AN13*1.02 -> 8073.8078
B14: Weapon and Ammunition revenue | C14: 210 | D14: 231 | G14: 216 | H14: 257 | I14: 228 | J14: =AB14-I14-H14-G14 -> 437 | K14: 174 | L14: 248 | M14: 379 | N14: =AC14-M14-L14-K14 -> 680 | O14: 321 | P14: 635 | Q14: 447 | R14: =AD14-Q14-P14-O14 -> 1132 | S14: 530 | T14: 661 | U14: =Q14*1.8 -> 804.6 | V14: =R14*1.2 -> 1358.4 | Z14: 1118 | AA14: 1139 | AB14: 1138 | AC14: 1481 | AD14: 2535 | AE14: =SUM(S14:V14) -> 3354 | AF14: =AE14*1.2 -> 4024.8 | AG14: =AF14*1.1 -> 4427.28 | AH14: =AG14*1.05 -> 4648.644 | AI14: =AH14*1.03 -> 4788.1033 | AJ14: =AI14*1.02 -> 4883.8654 | AK14: =AJ14*1.02 -> 4981.5427 | AL14: =AK14*1.02 -> 5081.1735 | AM14: =AL14*1.02 -> 5182.797 | AN14: =AM14*1.02 -> 5286.453 | AO14: =AN14*1.02 -> 5392.182
B15: Electronic Solutions revenue | C15: 141 | D15: 162 | G15: 132 | H15: 190 | I15: 186 | J15: =AB15-I15-H15-G15 -> 433 | K15: 185 | L15: 211 | M15: 204 | N15: =AC15-M15-L15-K15 -> 418 | O15: 227 | P15: 272 | Q15: 284 | R15: =AD15-Q15-P15-O15 -> 533 | S15: 335 | T15: 403 | U15: =Q15*1.4 -> 397.6 | V15: =R15*1.33 -> 708.89 | Z15: 776 | AA15: 745 | AB15: 941 | AC15: 1018 | AD15: 1316 | AE15: =SUM(S15:V15) -> 1844.49 | AF15: =AE15*1.22 -> 2250.2778 | AG15: =AF15*1.15 -> 2587.8195 | AH15: =AG15*1.08 -> 2794.845 | AI15: =AH15*1.05 -> 2934.5873 | AJ15: =AI15*1.04 -> 3051.9708 | AK15: =AJ15*1.03 -> 3143.5299 | AL15: =AK15*1.03 -> 3237.8358 | AM15: =AL15*1.03 -> 3334.9709 | AN15: =AM15*1.03 -> 3435.02 | AO15: =AN15*1.03 -> 3538.0706
B16: Power Systems revenue | C16: =351+158 -> 509 | D16: =307+159 -> 466 | G16: =326+190 -> 516 | H16: =325+183 -> 508 | I16: =339+187 -> 526 | J16: =AB16-I16-H16-G16 -> 502 | K16: 541 | L16: 484 | M16: =327+197 -> 524 | N16: =AC16-M16-L16-K16 -> 532 | O16: 540 | P16: 513 | Q16: 484 | R16: =AD16-Q16-P16-O16 -> 495 | S16: 504 | T16: 480 | U16: =Q16*0.95 -> 459.8 | V16: =R16*0.98 -> 485.1 | Z16: =1147+533 -> 1680 | AA16: =1229+647 -> 1876 | AB16: =1313+739 -> 2052 | AC16: =1346+735 -> 2081 | AD16: 2032 | AE16: =SUM(S16:V16) -> 1928.9 | AF16: =AE16*1.01 -> 1948.189 | AG16: =AF16*1.01 -> 1967.6709 | AH16: =AG16*1.01 -> 1987.3476 | AI16: =AH16*1.01 -> 2007.2211 | AJ16: =AI16*1.01 -> 2027.2933 | AK16: =AJ16*1.01 -> 2047.5662 | AL16: =AK16*1.01 -> 2068.0419 | AM16: =AL16*1.01 -> 2088.7223 | ... AO16: =AN16*1.01 -> 2130.7056
B17: Other revenue | C17: 2 | D17: -4 | G17: 7 | H17: 7 | I17: 9 | J17: =AB17-I17-H17-G17 -> 5 | K17: 6 | L17: 9 | M17: -2 | N17: =AC17-M17-L17-K17 -> 5 | O17: 5 | P17: 10 | Q17: 4 | R17: =AD17-Q17-P17-O17 -> 80 | S17: -9 | T17: -43 | U17: =Q17*1.35 -> 5.4 | V17: =R17*1.5 -> 120 | Z17: 3 | AA17: 24 | AB17: 28 | AC17: 18 | AD17: 99 | AE17: =SUM(S17:V17) -> 73.4 | AF17: =AE17*1.4 -> 102.76 | AG17: =AF17*1.3 -> 133.588 | AH17: =AG17*1.2 -> 160.3056 | AI17: =AH17*1.1 -> 176.33616 | AJ17: =AI17*1.05 -> 185.15297 | AK17: =AJ17*1.05 -> 194.41062 | AL17: =AK17*1.05 -> 204.13115 | AM17: =AL17*1.05 -> 214.3377 | AN17: =AM17*1.05 -> 225.05459 | AO17: =AN17*1.05 -> 236.30732
B18: Revenue | C18: 1268 | D18: =SUM(D13:D17) -> 1316 | G18: 1266 | H18: =SUM(H13:H17) -> 1408 | I18: 1415 | J18: =SUM(J13:J17) -> 2321 | K18: =SUM(K13:K17) -> 1363 | L18: =SUM(L13:L17) -> 1497 | M18: 1758 | N18: =SUM(N13:N17) -> 2557 | O18: =SUM(O13:O17) -> 1582 | P18: =SUM(P13:P17) -> 2235 | Q18: =SUM(Q13:Q17) -> 2453 | R18: =SUM(R13:R17) -> 3481 | S18: =SUM(S13:S17) -> 2305 | T18: =SUM(T13:T17) -> 2431 | U18: =SUM(U13:U17) -> 3148.2 | V18: =SUM(V13:V17) -> 4347.74 | Z18: =SUM(Z13:Z17) -> 5405 | AA18: =SUM(AA13:AA17) -> 5659 | AB18: =SUM(AB13:AB17) -> 6410 | AC18: =SUM(AC13:AC17) -> 7175 | AD18: 9751 | AE18: =SUM(AE13:AE17) -> 12231.94 | AF18: =SUM(AF13:AF17) -> 14464.03 | AG18: =SUM(AG13:AG17) -> 15745.402 | AH18: =SUM(AH13:AH17) -> 16551.638 | AI18: =SUM(AI13:AI17) -> 17075.558 | AJ18: =SUM(AJ13:AJ17) -> 17460.979 | AK18: =SUM(AK13:AK17) -> 17826 | AL18: =SUM(AL13:AL17) -> 18199.312 | ... AO18: =SUM(AO13:AO17) -> 19371.073
B19: Inventory cost | C19: -85 | D19: -29 | G19: -142 | H19: -86 | I19: -138 | J19: =AB19-I19-H19-G19 -> 213 | K19: -332 | L19: -213 | M19: -173 | N19: =AC19-M19-L19-K19 -> 22 | O19: -432 | P19: -1 | Q19: 130 | R19: =AD19-Q19-P19-O19 -> 136 | S19: -247 | T19: -353 | U19: 0 | V19: 0 | Z19: -142 | AA19: -117 | AB19: -153 | AC19: -696 | AD19: -167 | AF19: =AE19*0.97 -> 0 | AG19: =AF19*0.97 -> 0 | AH19: =AG19*0.97 -> 0 | AI19: =AH19*0.97 -> 0 | AJ19: =AI19*0.97 -> 0 | AK19: =AJ19*0.97 -> 0 | AL19: =AK19*0.97 -> 0 | AM19: =AL19*0.97 -> 0 | ... AO19: =AN19*0.97 -> 0
B20: Cost of materials | C20: 665 | D20: 635 | G20: 684 | H20: 714 | I20: 797 | J20: =AB20-I20-H20-G20 -> 988 | K20: 893 | L20: 861 | M20: 1007 | N20: =AC20-M20-L20-K20 -> 1174 | O20: 1039 | P20: 1087 | Q20: 1170 | R20: =AD20-Q20-P20-O20 -> 1563 | S20: 1314 | T20: 1485 | Z20: 2792 | AA20: 2745 | AB20: 3183 | AC20: 3935 | AD20: 4859 | AF20: =AF18*0.5 -> 7232.0149 | AG20: =AG18*0.5 -> 7872.7008 | AH20: =AH18*0.5 -> 8275.8188 | AI20: =AI18*0.5 -> 8537.779 | AJ20: =AJ18*0.5 -> 8730.4894 | AK20: =AK18*0.5 -> 8912.9999 | AL20: =AL18*0.5 -> 9099.6559 | AM20: =AM18*0.5 -> 9290.5599 | ... AO20: =AO18*0.5 -> 9685.5367
B21: Personnel costs | C21: 414 | D21: 423 | G21: 457 | H21: 464 | I21: 440 | J21: =AB21-I21-H21-G21 -> 475 | K21: 500 | L21: 507 | M21: 495 | N21: =AC21-M21-L21-K21 -> 545 | O21: 581 | P21: 578 | Q21: 572 | R21: =AD21-Q21-P21-O21 -> 642 | S21: 696 | T21: 704 | Z21: 1537 | AA21: 1643 | AB21: 1836 | AC21: 2047 | AD21: 2373 | AF21: =AF18*0.25 -> 3616.0075 | AG21: =AG18*0.25 -> 3936.3504 | AH21: =AH18*0.25 -> 4137.9094 | AI21: =AI18*0.25 -> 4268.8895 | AJ21: =AJ18*0.25 -> 4365.2447 | AK21: =AK18*0.25 -> 4456.5 | AL21: =AL18*0.25 -> 4549.8279 | AM21: =AM18*0.25 -> 4645.28 | ... AO21: =AO18*0.25 -> 4842.7683
B22: Total cost of sales | C22: =SUM(C19:C21) -> 994 | D22: =SUM(D19:D21) -> 1029 | G22: =SUM(G19:G21) -> 999 | H22: =SUM(H19:H21) -> 1092 | I22: =SUM(I19:I21) -> 1099 | J22: =SUM(J19:J21) -> 1676 | K22: =SUM(K19:K21) -> 1061 | L22: =SUM(L19:L21) -> 1155 | M22: =SUM(M19:M21) -> 1329 | N22: =SUM(N19:N21) -> 1741 | ... T22: =SUM(T19:T21) -> 1836 | U22: =U18-U23 -> 2329.668 | V22: =V18-V23 -> 2869.5084 | Z22: =SUM(Z19:Z21) -> 4187 | AA22: =SUM(AA19:AA21) -> 4271 | AB22: =SUM(AB19:AB21) -> 4866 | AC22: =SUM(AC19:AC21) -> 5286 | AD22: =SUM(AD19:AD21) -> 7065 | AE22: =SUM(S22:V22) -> 8798.1764 | AF22: =SUM(AF19:AF21) -> 10848.022 | AG22: =SUM(AG19:AG21) -> 11809.051 | AH22: =SUM(AH19:AH21) -> 12413.728 | AI22: =SUM(AI19:AI21) -> 12806.669 | AJ22: =SUM(AJ19:AJ21) -> 13095.734 | AK22: =SUM(AK19:AK21) -> 13369.5 | AL22: =SUM(AL19:AL21) -> 13649.484 | AM22: =SUM(AM19:AM21) -> 13935.84 | ... AO22: =SUM(AO19:AO21) -> 14528.305
B23: Gross profit | C23: =C18-C22 -> 274 | D23: =D18-D22 -> 287 | G23: =G18-G22 -> 267 | H23: =H18-H22 -> 316 | I23: =I18-I22 -> 316 | J23: =J18-J22 -> 645 | K23: =K18-K22 -> 302 | L23: =L18-L22 -> 342 | M23: =M18-M22 -> 429 | N23: =N18-N22 -> 816 | ... T23: =T18-T22 -> 595 | U23: =U18*0.26 -> 818.532 | V23: =V18*0.34 -> 1478.2316 | Z23: =Z18-Z22 -> 1218 | AA23: =AA18-AA22 -> 1388 | AB23: =AB18-AB22 -> 1544 | AC23: =AC18-AC22 -> 1889 | AD23: =AD18-AD22 -> 2686 | AE23: =AE18-AE22 -> 3433.7636 | AF23: =AF18-AF22 -> 3616.0075 | AG23: =AG18-AG22 -> 3936.3504 | ... AO23: =AO18-AO22 -> 4842.7683
B24: D&A | C24: 58 | D24: 58 | G24: 60 | H24: 62 | I24: 63 | J24: =AB24-I24-H24-G24 -> 64 | K24: 63 | L24: 63 | M24: 79 | N24: =AC24-M24-L24-K24 -> 103 | O24: 91 | P24: 91 | Q24: 95 | R24: =AD24-Q24-P24-O24 -> 126 | S24: 112 | T24: 127 | U24: 95 | V24: 130 | Z24: 282 | AA24: 251 | AB24: 249 | AC24: 308 | AD24: 403
B25: Other operating income | C25: -21 | D25: -30 | G25: -29 | H25: -39 | I25: -53 | J25: =AB25-I25-H25-G25 -> -100 | K25: -32 | L25: -22 | M25: -41 | N25: =AC25-M25-L25-K25 -> -58 | O25: -42 | P25: -39 | Q25: -51 | R25: =AD25-Q25-P25-O25 -> -96 | S25: -36 | T25: -51 | U25: =Q25*1.3 -> -66.3 | V25: =R25*1.3 -> -124.8 | Z25: -114 | AA25: -134 | AB25: -221 | AC25: -153 | AD25: -228
B26: Other operating expenses | C26: 149 | D26: 154 | G26: 153 | H26: 166 | I26: 194 | J26: =AB26-I26-H26-G26 -> 255 | K26: 182 | L26: 183 | M26: 219 | N26: =AC26-M26-L26-K26 -> 305 | O26: 228 | P26: 277 | Q26: 247 | R26: =AD26-Q26-P26-O26 -> 368 | S26: 287 | T26: 287 | U26: =Q26*1.15 -> 284.05 | V26: =R26*1.1 -> 404.8 | Z26: 642 | AA26: 656 | AB26: 768 | AC26: 889 | AD26: 1120
B27: Total operating expenses | C27: =SUM(C24:C26) -> 186 | D27: =SUM(D24:D26) -> 182 | G27: =SUM(G24:G26) -> 184 | H27: =SUM(H24:H26) -> 189 | I27: =SUM(I24:I26) -> 204 | J27: =SUM(J24:J26) -> 219 | K27: =SUM(K24:K26) -> 213 | L27: =SUM(L24:L26) -> 224 | M27: =SUM(M24:M26) -> 257 | N27: =SUM(N24:N26) -> 350 | ... V27: =SUM(V24:V26) -> 410 | Z27: =SUM(Z24:Z26) -> 810 | AA27: =SUM(AA24:AA26) -> 773 | AB27: =SUM(AB24:AB26) -> 796 | AC27: =SUM(AC24:AC26) -> 1044 | AD27: =SUM(AD24:AD26) -> 1295 | AE27: =SUM(S27:V27) -> 1448.75 | AF27: =(AE27*1.05) -> 1521.1875 | AG27: =AF27*1.04 -> 1582.035 | AH27: =AG27*1.03 -> 1629.4961 | AI27: =AH27*1.02 -> 1662.086 | AJ27: =AI27*1.02 -> 1695.3277 | AK27: =AJ27*1.02 -> 1729.2342 | AL27: =AK27*1.02 -> 1763.8189 | AM27: =AL27*1.02 -> 1799.0953 | AN27: =AM27*1.02 -> 1835.0772 | AO27: =AN27*1.02 -> 1871.7788
B28: Operating profit | C28: =C23-C27 -> 88 | D28: =D23-D27 -> 105 | G28: =G23-G27 -> 83 | H28: =H23-H27 -> 127 | I28: =I23-I27 -> 112 | J28: =J23-J27 -> 426 | K28: =K23-K27 -> 89 | L28: =L23-L27 -> 118 | M28: =M23-M27 -> 172 | N28: =N23-N27 -> 466 | ... V28: =V23-V27 -> 1068.2316 | Z28: =Z23-Z27 -> 408 | AA28: =AA23-AA27 -> 615 | AB28: =AB23-AB27 -> 748 | AC28: =AC23-AC27 -> 845 | AD28: =AD23-AD27 -> 1391 | AE28: =AE23-AE27 -> 1985.0136 | AF28: =AF23-AF27 -> 2094.82 | AG28: =AG23-AG27 -> 2354.3154 | ... AO28: =AO23-AO27 -> 2970.9896
B29: Investments | C29: -7 | D29: -4 | G29: -17 | H29: 2 | I29: -8 | J29: =AB29-I29-H29-G29 -> -16 | K29: 10 | L29: 2 | M29: -6 | N29: =AC29-M29-L29-K29 -> -63 | O29: 1 | P29: 4 | Q29: 12 | R29: =AD29-Q29-P29-O29 -> 20 | S29: 3 | T29: 0 | Z29: -13 | AA29: -11 | AB29: -39 | AC29: -57 | AD29: 37
B30: Other financial income | C30: 10 | D30: 1 | G30: 20 | H30: 21 | I30: 3 | J30: =AB30-I30-H30-G30 -> 4 | K30: 2 | L30: -3 | M30: 8 | N30: =AC30-M30-L30-K30 -> -1 | O30: 9 | P30: 2 | Q30: 8 | R30: =AD30-Q30-P30-O30 -> -9 | S30: 3 | T30: -7 | Z30: 24 | AA30: 17 | AB30: 48 | AC30: 6 | AD30: 10
B31: Interest income | C31: -2 | D31: -2 | G31: -1 | H31: -1 | I31: -1 | J31: =AB31-I31-H31-G31 -> -9 | K31: -16 | L31: -3 | M31: -5 | N31: =AC31-M31-L31-K31 -> -5 | O31: -5 | P31: -4 | Q31: -5 | R31: =AD31-Q31-P31-O31 -> -5 | S31: -6 | T31: -4 | Z31: -9 | AA31: -4 | AB31: -12 | AC31: -29 | AD31: -19
B32: Interest expense | C32: 11 | D32: 7 | G32: 8 | H32: 7 | I32: 7 | J32: =AB32-I32-H32-G32 -> 10 | K32: 24 | L32: 18 | M32: 30 | N32: =AC32-M32-L32-K32 -> 39 | O32: 26 | P32: 32 | Q32: 28 | R32: =AD32-Q32-P32-O32 -> 49 | S32: 33 | T32: 20 | Z32: 40 | AA32: 31 | AB32: 32 | AC32: 111 | AD32: 135
B33: Net financial expense | C33: =SUM(C29:C32) -> 12 | D33: =SUM(D29:D32) -> 2 | G33: =SUM(G29:G32) -> 10 | H33: =SUM(H29:H32) -> 29 | I33: =SUM(I29:I32) -> 1 | J33: =SUM(J29:J32) -> -11 | K33: =SUM(K29:K32) -> 20 | L33: =SUM(L29:L32) -> 14 | M33: =SUM(M29:M32) -> 27 | N33: =SUM(N29:N32) -> -30 | ... T33: =SUM(T29:T32) -> 9 | U33: =Q33*1.05 -> 45.15 | V33: =R33*1.05 -> 57.75 | Z33: =SUM(Z29:Z32) -> 42 | AA33: =SUM(AA29:AA32) -> 33 | AB33: =SUM(AB29:AB32) -> 29 | AC33: =SUM(AC29:AC32) -> 31 | AD33: =SUM(AD29:AD32) -> 163 | AE33: =SUM(S33:V33) -> 144.9 | AF33: =AE33*1.03 -> 149.247 | AG33: =AF33*1.03 -> 153.72441 | AH33: =AG33*1.03 -> 158.33614 | AI33: =AH33*1.03 -> 163.08623 | AJ33: =AI33*1.03 -> 167.97881 | AK33: =AJ33*1.03 -> 173.01818 | AL33: =AK33*1.03 -> 178.20872 | AM33: =AL33*1.03 -> 183.55498 | ... AO33: =AN33*1.03 -> 194.73348
B34: Pretax profit | C34: =C28-C33 -> 76 | D34: =D28-D33 -> 103 | G34: =G28-G33 -> 73 | H34: =H28-H33 -> 98 | I34: =I28-I33 -> 111 | J34: =J28-J33 -> 437 | K34: =K28-K33 -> 69 | L34: =L28-L33 -> 104 | M34: =M28-M33 -> 145 | N34: =N28-N33 -> 496 | ... V34: =V28-V33 -> 1010.4816 | Z34: =Z28-Z33 -> 366 | AA34: =AA28-AA33 -> 582 | AB34: =AB28-AB33 -> 719 | AC34: =AC28-AC33 -> 814 | AD34: =AD28-AD33 -> 1228 | AE34: =AE28-AE33 -> 1840.1136 | AF34: =AF28-AF33 -> 1945.573 | AG34: =AG28-AG33 -> 2200.591 | ... AO34: =AO28-AO33 -> 2776.2561
B35: Taxes | C35: 21 | D35: 24 | G35: 15 | H35: 30 | I35: 30 | J35: =AB35-I35-H35-G35 -> 108 | K35: 20 | L35: 31 | M35: 36 | N35: =AC35-M35-L35-K35 -> 98 | O35: 31 | P35: 56 | Q35: 74 | R35: =AD35-Q35-P35-O35 -> 172 | S35: 39 | T35: 53 | U35: =U34*0.27 -> 124.37064 | V35: =V34*0.27 -> 272.83003 | Z35: 83 | AA35: 150 | AB35: 183 | AC35: 185 | AD35: 333 | AE35: =SUM(S35:V35) -> 489.20067 | AF35: =AF34*0.25 -> 486.39324 | AG35: =AG34*0.25 -> 550.14775 | AH35: =AH34*0.25 -> 587.5193 | AI35: =AI34*0.25 -> 610.92933 | AJ35: =AJ34*0.25 -> 625.48455 | AK35: =AK34*0.25 -> 638.56188 | AL35: =AL34*0.25 -> 651.95007 | AM35: =AM34*0.25 -> 665.65742 | ... AO35: =AO34*0.25 -> 694.06402
B36: MI | C36: =-4+9 -> 5 | D36: =103+13 -> 116 | G36: =-1+13 -> 12 | H36: =-5+16 -> 11 | I36: =-5+10 -> 5 | J36: =AB36-I36-H36-G36 -> 32 | K36: =4-3 -> 1 | L36: =17-1 -> 16 | M36: =-2+9 -> 7 | N36: =AC36-M36-L36-K36 -> 71 | O36: =-1+6 -> 5 | P36: =17+72 -> 89 | Q36: 38 | R36: =AD36-Q36-P36-O36 -> 46 | S36: 24 | T36: 27 | U36: =U34*0.1 -> 46.0632 | V36: =V34*0.1 -> 101.04816 | Z36: =283+27 -> 310 | AA36: =100+41 -> 141 | AB36: =-6+66 -> 60 | AC36: =44+51 -> 95 | AD36: =87+91 -> 178 | AE36: =SUM(S36:V36) -> 198.11136 | AF36: =AF34*0.1 -> 194.5573 | AG36: =AG34*0.1 -> 220.0591 | AH36: =AH34*0.1 -> 235.00772 | AI36: =AI34*0.1 -> 244.37173 | AJ36: =AJ34*0.1 -> 250.19382 | AK36: =AK34*0.1 -> 255.42475 | AL36: =AL34*0.1 -> 260.78003 | AM36: =AM34*0.1 -> 266.26297 | ... AO36: =AO34*0.1 -> 277.62561
B37: Net profit | C37: =C34-C35-C36 -> 50 | D37: =D34-D35-D36 -> -37 | G37: =G34-G35-G36 -> 46 | H37: =H34-H35-H36 -> 57 | I37: =I34-I35-I36 -> 76 | J37: =J34-J35-J36 -> 297 | K37: =K34-K35-K36 -> 48 | L37: =L34-L35-L36 -> 57 | M37: =M34-M35-M36 -> 102 | N37: =N34-N35-N36 -> 327 | ... V37: =V34-V35-V36 -> 636.60341 | Z37: =Z34-Z35-Z36 -> -27 | AA37: =AA34-AA35-AA36 -> 291 | AB37: =AB34-AB35-AB36 -> 476 | AC37: =AC34-AC35-AC36 -> 534 | AD37: =AD34-AD35-AD36 -> 717 | AE37: =AE34-AE35-AE36 -> 1152.8016 | AF37: =AF34-AF35-AF36 -> 1264.6224 | AG37: =AG34-AG35-AG36 -> 1430.3841 | ... AO37: =AO34-AO35-AO36 -> 1804.5665 | AP37: =AO37*(1+$AS$45) -> 1786.5208 | AQ37: =AP37*(1+$AS$45) -> 1768.6556 | AR37: =AQ37*(1+$AS$45) -> 1750.969 | AS37: =AR37*(1+$AS$45) -> 1733.4593 | AT37: =AS37*(1+$AS$45) -> 1716.1247 | AU37: =AT37*(1+$AS$45) -> 1698.9635 | AV37: =AU37*(1+$AS$45) -> 1681.9739 | AW37: =AV37*(1+$AS$45) -> 1665.1541 | ... EV37: =EU37*(1+$AS$45) -> 591.3975
B38: Shares | C38: 43.43 | D38: 43.43 | G38: 43.43 | H38: 43.43 | I38: 43.43 | J38: 43.43 | K38: 43.43 | L38: 43.43 | M38: 43.43 | N38: 43.43 | O38: 43.43 | P38: 43.43 | Q38: 43.43 | R38: 43.43 | S38: 43.84 | T38: 43.84 | U38: 43.84 | V38: 43.84 | Z38: 43.43 | AA38: 43.43 | AB38: 43.43 | AC38: 43.43 | AD38: 43.43 | AE38: 43.84 | AF38: 43.84 | AG38: 43.84 | AH38: 43.84 | AI38: 43.84 | AJ38: 43.84 | AK38: 43.84 | AL38: 43.84 | AM38: 43.84 | AN38: 43.84 | AO38: 43.84
B39: EPS | C39: =C37/C38 -> 1.1512779 | D39: =D37/D38 -> -0.85194566 | G39: =G37/G38 -> 1.0591757 | H39: =H37/H38 -> 1.3124568 | I39: =I37/I38 -> 1.7499424 | J39: =J37/J38 -> 6.8385908 | K39: =K37/K38 -> 1.1052268 | L39: =L37/L38 -> 1.3124568 | M39: =M37/M38 -> 2.348607 | N39: =N37/N38 -> 7.5293576 | ... V39: =V37/V38 -> 14.521063 | Z39: =Z37/Z38 -> -0.62169008 | AA39: =AA37/AA38 -> 6.7004375 | AB39: =AB37/AB38 -> 10.960166 | AC39: =AC37/AC38 -> 12.295648 | AD39: =AD37/AD38 -> 16.509325 | AE39: =AE37/AE38 -> 26.295656 | AF39: =AF37/AF38 -> 28.846314 | AG39: =AG37/AG38 -> 32.627376 | ... AO39: =AO37/AO38 -> 41.162556
B41: Order Backlog y/y | O41: =O10/K10-1 -> 0.53728587 | P41: =P10/L10-1 -> 0.5376619 | Q41: =Q10/M10-1 -> 0.41511822 | R41: =R10/N10-1 -> 0.39818902 | S41: =S10/O10-1 -> 0.34958575 | T41: =T10/P10-1 -> 0.16647988 | AC41: =AC10/AB10-1 -> 0.45649148 | AD41: =AD10/AC10-1 -> 0.39818902
B42: Backlog y/y | N42: =N11/J11-1 -> 0.44099052 | O42: =O11/K11-1 -> 0.42572888 | P42: =P11/L11-1 -> 0.61863561 | Q42: =Q11/M11-1 -> 0.4126388 | R42: =R11/N11-1 -> 0.43570123 | S42: =S11/O11-1 -> 0.55633505 | T42: =T11/P11-1 -> 0.29862253 | AC42: =AC11/AB11-1 -> 0.44095288 | AD42: =AD11/AC11-1 -> 0.43573872
B44: Vehicle Systems revenue y/y | G44: =G13/C13-1 -> -0.027093596 | H44: =H13/D13-1 -> -0.032537961 | K44: =K13/G13-1 -> 0.15696203 | L44: =L13/H13-1 -> 0.22197309 | M44: =M13/I13-1 -> 0.40128755 | N44: =N13/J13-1 -> -0.023305085 | O44: =O13/K13-1 -> 0.070021882 | P44: =P13/L13-1 -> 0.47706422 | Q44: =Q13/M13-1 -> 0.88973966 | R44: =R13/N13-1 -> 0.34598698 | ... V44: =V13/R13-1 -> 0.35 | AA44: =AA13/Z13-1 -> 0.02571116 | AB44: =AB13/AA13-1 -> 0.20053333 | AC44: =AC13/AB13-1 -> 0.14482452 | AD44: =AD13/AC13-1 -> 0.46255336 | AE44: =AE13/AD13-1 -> 0.33487663 | AF44: =AF13/AE13-1 -> 0.22 | AG44: =AG13/AF13-1 -> 0.08 | AH44: =AH13/AG13-1 -> 0.05 | ... AO44: =AO13/AN13-1 -> 0.02
...
