Workbook

Sheet Main
E2: Time last checked | F2: Today | G2: Earnings
B3: 7203 | C3: Price | D3: 199.06 | E3: 45995 | F3: =TODAY() -> 45995 | G3: 46064
C4: Shares | D4: =(15795-2762)/10 -> 1303.3 | E4: Q226
C5: MC | D5: =D3*D4 -> 259434.9
C6: Cash JPY | D6: =8982404+5798051 -> 14780455 | E6: Q226
C7: Debt JPY | D7: =15829516+22963363 -> 38792879 | E7: Q226
C8: Cash USD | D8: =D6/D13 -> 95499.483 | E8: Q226
C9: Debt USD | D9: =D7/D13 -> 250648.57 | E9: Q226
C10: Net Cash | D10: =(D6-D7)/D13 -> -155149.09 | E10: Q226
C11: EV | D11: =D5-D10 -> 414583.98
C13: USD/JPY | D13: 154.77
I15: =(2766-43+47)*(6886/D13)+(43/2)*D3 -> 127522.15

Sheet Model
C1: 43646 | D1: 43738 | E1: 43830 | F1: 43921 | G1: 44012 | H1: 44104 | I1: 44196 | J1: 44286 | K1: 44377 | L1: 44469 | M1: 44561 | N1: 44651 | O1: 44742 | P1: 44834 | Q1: 44926 | R1: 45016 | S1: 45107 | T1: 45199 | U1: 45291 | V1: 45382 | W1: 45473 | X1: 45565 | Y1: 45657 | Z1: 45747 | AA1: 45838 | AB1: 45930 | AC1: 46022 | AD1: 46112 | AF1: 42825 | AG1: 43190 | AH1: 43555 | AI1: 43921 | AJ1: 44286 | AK1: 44651 | AL1: 45016 | AM1: 45382 | AN1: 45747 | AO1: 46112 | AP1: 46477 | AQ1: 46843 | AR1: 47208 | AS1: 47573 | AT1: 47938 | AU1: 48304 | AV1: 48669 | AW1: 49034 | AX1: 49399
C2: Q120 | D2: Q220 | E2: Q320 | F2: Q420 | G2: Q121 | H2: Q221 | I2: Q321 | J2: Q421 | K2: Q122 | L2: Q222 | M2: Q322 | N2: Q422 | O2: Q123 | P2: Q223 | Q2: Q323 | R2: Q423 | S2: Q124 | T2: Q224 | U2: Q324 | V2: Q424 | W2: Q125 | X2: Q225 | Y2: Q325 | Z2: Q425 | AA2: Q126 | AB2: Q226 | AC2: Q326 | AD2: Q426 | AF2: 2017 | AG2: 2018 | AH2: 2019 | AI2: 2020 | AJ2: 2021 | AK2: 2022 | AL2: 2023 | AM2: 2024 | AN2: 2025 | AO2: 2026 | AP2: 2027 | AQ2: 2028 | AR2: 2029 | AS2: 2030 | AT2: 2031 | AU2: 2032 | AV2: 2033 | AW2: 2034 | AX2: 2035
B3: Revenue | C3: =C32/Main!$D$13 -> 49888.693 | D3: =D32/Main!$D$13 -> 49344.214 | E3: =E32/Main!$D$13 -> 49162.829 | F3: =F32/Main!$D$13 -> 44578.013 | G3: =G32/Main!$D$13 -> 29726.665 | H3: =H32/Main!$D$13 -> 43770.931 | I3: =I32/Main!$D$13 -> 52658.991 | J3: =F3*1.15 -> 51264.714 | W3: =W32/Main!$D$13 -> 76486.91 | X3: =X32/Main!$D$13 -> 73945.668 | AA3: =AA32/Main!$D$13 -> 79171.196 | AB3: =AB32/Main!$D$13 -> 79973.037 | AF3: =AF32/Main!$D$13 -> 178311 | AG3: =AG32/Main!$D$13 -> 189826.9 | AH3: =AH32/Main!$D$13 -> 195294.18 | AI3: =AI32/Main!$D$13 -> 192973.75 | AJ3: =AJ32/Main!$D$13 -> 175838.95 | AK3: =AK32/Main!$D$13 -> 202749.29 | AL3: =AL32/Main!$D$13 -> 240061.37 | AM3: =AM32/Main!$D$13 -> 291369.94 | AN3: =AN32/Main!$D$13 -> 310374.78 | AO3: =AN3*1.04 -> 322789.77 | AP3: =AO3*1.02 -> 329245.56 | AQ3: =AP3*1.01 -> 332538.02 | AR3: =AQ3*1.01 -> 335863.4 | AS3: =AR3*1.01 -> 339222.03 | AT3: =AS3*1.01 -> 342614.25 | AU3: =AT3*1.01 -> 346040.39 | AV3: =AU3*1.01 -> 349500.8 | AW3: =AV3*1.01 -> 352995.81 | AX3: =AW3*1.01 -> 356525.76
B4: Cost of sales | C4: =C33/Main!$D$13 -> 40506.203 | D4: =D33/Main!$D$13 -> 40611.307 | E4: =E33/Main!$D$13 -> 40232.319 | F4: =F33/Main!$D$13 -> 36854.933 | G4: =G33/Main!$D$13 -> 26176.701 | H4: =H33/Main!$D$13 -> 36352.523 | I4: =I33/Main!$D$13 -> 41954.707 | J4: =J3-J5 -> 42037.066 | W4: =W33/Main!$D$13 -> 60793.332 | X4: =X33/Main!$D$13 -> 58192.996 | AA4: =AA33/Main!$D$13 -> 64983.608 | AB4: =AB33/Main!$D$13 -> 67251.98 | AF4: =AF33/Main!$D$13 -> 146891.1 | AG4: =AG33/Main!$D$13 -> 154352.61 | AH4: =AH33/Main!$D$13 -> 160120.08 | AI4: =AI33/Main!$D$13 -> 158204.76 | AJ4: =AJ33/Main!$D$13 -> 144616.01 | AK4: =AK33/Main!$D$13 -> 164165.11 | AL4: =AL33/Main!$D$13 -> 199271.71 | AM4: =AM33/Main!$D$13 -> 230839.36 | AN4: =AN33/Main!$D$13 -> 248489.15 | AO4: =AO3-AO5 -> 267915.51 | AP4: =AP3-AP5 -> 273273.82 | AQ4: =AQ3-AQ5 -> 272681.17 | AR4: =AR3-AR5 -> 272049.35 | AS4: =AS3-AS5 -> 274769.85 | AT4: =AT3-AT5 -> 277517.54 | AU4: =AU3-AU5 -> 280292.72 | AV4: =AV3-AV5 -> 283095.65 | ... AX4: =AX3-AX5 -> 288785.87
B5: Gross profit | C5: =C34/Main!$D$13 -> 9382.4901 | D5: =D34/Main!$D$13 -> 8732.9069 | E5: =E34/Main!$D$13 -> 8930.5098 | F5: =F34/Main!$D$13 -> 7723.0794 | G5: =G34/Main!$D$13 -> 3549.9645 | H5: =H34/Main!$D$13 -> 7418.408 | I5: =I34/Main!$D$13 -> 10704.284 | J5: =J3*0.18 -> 9227.6486 | W5: =W34/Main!$D$13 -> 15693.578 | X5: =X34/Main!$D$13 -> 15752.672 | AA5: =AA34/Main!$D$13 -> 14187.588 | AB5: =AB34/Main!$D$13 -> 12721.057 | AF5: =AF34/Main!$D$13 -> 31419.894 | AG5: =AG34/Main!$D$13 -> 35474.297 | AH5: =AH34/Main!$D$13 -> 35174.104 | AI5: =AI34/Main!$D$13 -> 34768.986 | AJ5: =AJ34/Main!$D$13 -> 31222.937 | AK5: =AK34/Main!$D$13 -> 38584.177 | AL5: =AL34/Main!$D$13 -> 40789.662 | AM5: =AM34/Main!$D$13 -> 60530.581 | AN5: =AN34/Main!$D$13 -> 61885.624 | AO5: =AO3*0.17 -> 54874.26 | AP5: =AP3*0.17 -> 55971.746 | AQ5: =AQ3*0.18 -> 59856.843 | AR5: =AR3*0.19 -> 63814.046 | AS5: =AS3*0.19 -> 64452.186 | AT5: =AT3*0.19 -> 65096.708 | AU5: =AU3*0.19 -> 65747.675 | AV5: =AV3*0.19 -> 66405.152 | AW5: =AW3*0.19 -> 67069.203 | AX5: =AX3*0.19 -> 67739.895
B6: SG&A | C6: =C35/Main!$D$13 -> 4597.254 | D6: =D35/Main!$D$13 -> 4477.515 | E6: =E35/Main!$D$13 -> 4794.7147 | F6: =F35/Main!$D$13 -> 5397.59 | G6: =G35/Main!$D$13 -> 3460.0246 | H6: =H35/Main!$D$13 -> 4148.6464 | I6: =I35/Main!$D$13 -> 4321.0054 | J6: =F6*0.92 -> 4965.7828 | W6: =W35/Main!$D$13 -> 7236.4412 | X6: =X35/Main!$D$13 -> 8288.008 | AA6: =AA35/Main!$D$13 -> 6652.9172 | AB6: =AB35/Main!$D$13 -> 7296.5497 | AF6: =AF35/Main!$D$13 -> 18533.857 | AG6: =AG35/Main!$D$13 -> 19968.308 | AH6: =AH35/Main!$D$13 -> 19230.801 | AI6: =AI35/Main!$D$13 -> 19267.074 | AJ6: =AJ35/Main!$D$13 -> 17022.84 | AK6: =AK35/Main!$D$13 -> 19228.384 | AL6: =AL35/Main!$D$13 -> 23182.723 | AM6: =AM35/Main!$D$13 -> 25944.195 | AN6: =AN35/Main!$D$13 -> 30900.381 | AO6: =AN6*1.02 -> 31518.389 | AP6: =AO6*1.01 -> 31833.573 | AQ6: =AP6*1.01 -> 32151.908 | AR6: =AQ6*1.01 -> 32473.428 | AS6: =AR6*1.01 -> 32798.162 | AT6: =AS6*1.01 -> 33126.143 | AU6: =AT6*1.01 -> 33457.405 | AV6: =AU6*1.01 -> 33791.979 | AW6: =AV6*1.01 -> 34129.899 | AX6: =AW6*1.01 -> 34471.198
B7: Operating profit | C7: =C36/Main!$D$13 -> 4785.2362 | D7: =D36/Main!$D$13 -> 4255.3919 | E7: =E36/Main!$D$13 -> 4135.7951 | F7: =F36/Main!$D$13 -> 2325.4894 | G7: =G36/Main!$D$13 -> 89.939911 | H7: =H36/Main!$D$13 -> 3269.7616 | I7: =I36/Main!$D$13 -> 6383.2784 | J7: =J5-J6 -> 4261.8658 | W7: =W36/Main!$D$13 -> 8457.1364 | X7: =X36/Main!$D$13 -> 7464.6637 | AA7: =AA36/Main!$D$13 -> 7534.6708 | AB7: =AB36/Main!$D$13 -> 5424.5073 | AF7: =AF36/Main!$D$13 -> 12886.037 | AG7: =AG36/Main!$D$13 -> 15505.99 | AH7: =AH36/Main!$D$13 -> 15943.303 | AI7: =AI36/Main!$D$13 -> 15501.913 | AJ7: =AJ36/Main!$D$13 -> 14200.097 | AK7: =AK36/Main!$D$13 -> 19355.792 | AL7: =AL36/Main!$D$13 -> 17606.939 | AM7: =AM36/Main!$D$13 -> 34586.386 | AN7: =AN36/Main!$D$13 -> 30985.243 | AO7: =AO5-AO6 -> 23355.871 | AP7: =AP5-AP6 -> 24138.173 | AQ7: =AQ5-AQ6 -> 27704.935 | AR7: =AR5-AR6 -> 31340.618 | AS7: =AS5-AS6 -> 31654.024 | AT7: =AT5-AT6 -> 31970.564 | AU7: =AU5-AU6 -> 32290.27 | AV7: =AV5-AV6 -> 32613.173 | ... AX7: =AX5-AX6 -> 33268.698
B8: Investments | C8: =C37/Main!$D$13 -> -676.77198 | D8: =D37/Main!$D$13 -> -614.60231 | E8: =E37/Main!$D$13 -> -489.9916 | F8: =F37/Main!$D$13 -> -223.20217 | G8: =G37/Main!$D$13 -> 81.230213 | H8: =H37/Main!$D$13 -> -574.80132 | I8: =I37/Main!$D$13 -> -808.1928 | J8: -300 | W8: =W37/Main!$D$13 -> -1065.691 | X8: =X37/Main!$D$13 -> -642.10118 | AA8: =AA37/Main!$D$13 -> -911.31356 | AB8: =AB37/Main!$D$13 -> -850.16476 | AI8: =AI37/Main!$D$13 -> -2004.5681 | AJ8: =AJ37/Main!$D$13 -> -2268.0687 | AK8: =AK37/Main!$D$13 -> -3620.5079 | AL8: =AL37/Main!$D$13 -> -4154.959 | AM8: =AM37/Main!$D$13 -> -4930.7812 | AN8: =AN37/Main!$D$13 -> -3819.9845 | AO8: =AN8*1.02 -> -3896.3842 | AP8: =AO8*1.02 -> -3974.3119 | AQ8: =AP8*1.02 -> -4053.7981 | AR8: =AQ8*1.02 -> -4134.8741 | AS8: =AR8*1.02 -> -4217.5715 | AT8: =AS8*1.02 -> -4301.923 | AU8: =AT8*1.02 -> -4387.9614 | AV8: =AU8*1.02 -> -4475.7207 | ... AX8: =AW8*1.02 -> -4656.5398
B9: Other finance income | C9: =C38/Main!$D$13 -> -501.07256 | D9: =D38/Main!$D$13 -> -414.49893 | E9: =E38/Main!$D$13 -> -394.73412 | F9: =F38/Main!$D$13 -> -665.82671 | G9: =G38/Main!$D$13 -> -741.67474 | H9: =H38/Main!$D$13 -> -343.63895 | I9: =I38/Main!$D$13 -> -341.66182 | J9: -300 | W9: =W38/Main!$D$13 -> -1122.9566 | X9: =X38/Main!$D$13 -> -627.67332 | AA9: =AA38/Main!$D$13 -> -993.2222 | AB9: =AB38/Main!$D$13 -> -898.2684 | AI9: =AI38/Main!$D$13 -> -1976.1323 | AJ9: =AJ38/Main!$D$13 -> -2812.1018 | AK9: =AK38/Main!$D$13 -> -2162.9515 | AL9: =AL38/Main!$D$13 -> -2451.0564 | AM9: =AM38/Main!$D$13 -> -4828.0416 | AN9: =AN38/Main!$D$13 -> -3596.9503 | AO9: =AN9*1.02 -> -3668.8893 | AP9: =AO9*1.02 -> -3742.2671 | AQ9: =AP9*1.02 -> -3817.1124 | AR9: =AQ9*1.02 -> -3893.4547 | AS9: =AR9*1.02 -> -3971.3238 | AT9: =AS9*1.02 -> -4050.7503 | AU9: =AT9*1.02 -> -4131.7653 | AV9: =AU9*1.02 -> -4214.4006 | ... AX9: =AW9*1.02 -> -4384.6624
B10: Other finance costs | C10: =C39/Main!$D$13 -> 63.591135 | D10: =D39/Main!$D$13 -> 82.102475 | E10: =E39/Main!$D$13 -> 76.571687 | F10: =F39/Main!$D$13 -> 82.412612 | G10: =G39/Main!$D$13 -> 64.689539 | H10: =H39/Main!$D$13 -> 85.449376 | I10: =I39/Main!$D$13 -> 63.700976 | J10: 93 | W10: =W39/Main!$D$13 -> 106.66796 | X10: =X39/Main!$D$13 -> 240.25974 | AA10: =AA39/Main!$D$13 -> 40.130516 | AB10: =AB39/Main!$D$13 -> 121.46411 | AI10: =AI39/Main!$D$13 -> 304.67791 | AJ10: =AJ39/Main!$D$13 -> 307.14609 | AK10: =AK39/Main!$D$13 -> 284.27344 | AL10: =AL39/Main!$D$13 -> 795.45778 | AM10: =AM39/Main!$D$13 -> 670.08464 | AN10: =AN39/Main!$D$13 -> 1232.222 | AO10: =AN10*1.02 -> 1256.8664 | AP10: =AO10*1.02 -> 1282.0038 | AQ10: =AP10*1.02 -> 1307.6439 | AR10: =AQ10*1.02 -> 1333.7967 | AS10: =AR10*1.02 -> 1360.4727 | AT10: =AS10*1.02 -> 1387.6821 | AU10: =AT10*1.02 -> 1415.4358 | AV10: =AU10*1.02 -> 1443.7445 | ... AX10: =AW10*1.02 -> 1502.0718
B11: Finance income | C11: =C40/Main!$D$13 -> 407.4433 | D11: =D40/Main!$D$13 -> 130.85223 | E11: =E40/Main!$D$13 -> -170.09756 | F11: =F40/Main!$D$13 -> 243.15436 | G11: =G40/Main!$D$13 -> -54.984816 | H11: =H40/Main!$D$13 -> 133.71454 | I11: =I40/Main!$D$13 -> 4.0188667 | J11: 50 | W11: =W40/Main!$D$13 -> -1531.2981 | X11: =X40/Main!$D$13 -> 2996.7694 | AA11: =AA40/Main!$D$13 -> 1372.1975 | AB11: =AB40/Main!$D$13 -> -1031.1301 | AI11: =AI40/Main!$D$13 -> 611.35233 | AJ11: =AJ40/Main!$D$13 -> -97.835498 | AK11: =AK40/Main!$D$13 -> -1396.8276 | AL11: =AL40/Main!$D$13 -> -804.52284 | AM11: =AM40/Main!$D$13 -> -1211.9145 | AN11: =AN40/Main!$D$13 -> -4557.033 | AO11: =AN11*1.02 -> -4648.1737 | AP11: =AO11*1.02 -> -4741.1372 | AQ11: =AP11*1.02 -> -4835.9599 | AR11: =AQ11*1.02 -> -4932.6791 | AS11: =AR11*1.02 -> -5031.3327 | AT11: =AS11*1.02 -> -5131.9593 | AU11: =AT11*1.02 -> -5234.5985 | AV11: =AU11*1.02 -> -5339.2905 | ... AX11: =AW11*1.02 -> -5554.9978
B12: Other income | C12: =C41/Main!$D$13 -> -6.3319765 | D12: =D41/Main!$D$13 -> 91.018931 | E12: =E41/Main!$D$13 -> 126.37462 | F12: =F41/Main!$D$13 -> 309.75641 | G12: =G41/Main!$D$13 -> -23.253861 | H12: =H41/Main!$D$13 -> 23.945209 | I12: =I41/Main!$D$13 -> 92.065646 | J12: 0 | W12: =W41/Main!$D$13 -> -29.527686 | X12: =X41/Main!$D$13 -> -55.094657 | AA12: =AA41/Main!$D$13 -> -63.526523 | AB12: =AB41/Main!$D$13 -> 161.33618 | AI12: =AI41/Main!$D$13 -> 520.81799 | AJ12: =AJ41/Main!$D$13 -> 124.42334 | AK12: =AK41/Main!$D$13 -> 468.18505 | AL12: =AL41/Main!$D$13 -> 504.67791 | AM12: =AM41/Main!$D$13 -> -115.77179 | AN12: =AN41/Main!$D$13 -> 281.04284 | AO12: =AN12*1.02 -> 286.66369 | AP12: =AO12*1.02 -> 292.39697 | AQ12: =AP12*1.02 -> 298.24491 | AR12: =AQ12*1.02 -> 304.20981 | AS12: =AR12*1.02 -> 310.294 | AT12: =AS12*1.02 -> 316.49988 | AU12: =AT12*1.02 -> 322.82988 | AV12: =AU12*1.02 -> 329.28648 | ... AX12: =AW12*1.02 -> 342.58965
B13: Net financing expense | C13: =C42/Main!$D$13 -> -713.14208 | D13: =D42/Main!$D$13 -> -725.12761 | E13: =E42/Main!$D$13 -> -851.87698 | F13: =F42/Main!$D$13 -> -253.7055 | G13: =G42/Main!$D$13 -> -673.99367 | H13: =H42/Main!$D$13 -> -675.33114 | I13: =I42/Main!$D$13 -> -990.06913 | J13: =SUM(J8:J12) -> -457 | W13: =W42/Main!$D$13 -> -3642.8055 | X13: =X42/Main!$D$13 -> 1912.16 | AA13: =AA42/Main!$D$13 -> -555.73432 | AB13: =AB42/Main!$D$13 -> -2496.7629 | AF13: =AF42/Main!$D$13 -> -1288.7058 | AG13: =AG42/Main!$D$13 -> -1425.1276 | AH13: =AH42/Main!$D$13 -> 1176.4554 | AI13: =AI42/Main!$D$13 -> -2543.8522 | AJ13: =AJ42/Main!$D$13 -> -4746.4366 | AK13: =AK42/Main!$D$13 -> -6427.8284 | AL13: =AL42/Main!$D$13 -> -6110.4025 | AM13: =AM42/Main!$D$13 -> -10416.424 | AN13: =AN42/Main!$D$13 -> -10460.703 | AO13: =SUM(AO8:AO12) -> -10669.917 | AP13: =SUM(AP8:AP12) -> -10883.315 | AQ13: =SUM(AQ8:AQ12) -> -11100.982 | AR13: =SUM(AR8:AR12) -> -11323.001 | AS13: =SUM(AS8:AS12) -> -11549.461 | AT13: =SUM(AT8:AT12) -> -11780.451 | AU13: =SUM(AU8:AU12) -> -12016.06 | AV13: =SUM(AV8:AV12) -> -12256.381 | ... AX13: =SUM(AX8:AX12) -> -12751.539
B14: Pretax income | C14: =C43/Main!$D$13 -> 5498.3782 | D14: =D43/Main!$D$13 -> 4980.5195 | E14: =E43/Main!$D$13 -> 4987.672 | F14: =F43/Main!$D$13 -> 2579.1949 | G14: =G43/Main!$D$13 -> 763.93358 | H14: =H43/Main!$D$13 -> 3945.0927 | I14: =I43/Main!$D$13 -> 7373.3475 | J14: =J7-J13 -> 4718.8658 | W14: =W43/Main!$D$13 -> 12099.942 | X14: =X43/Main!$D$13 -> 5552.5037 | AA14: =AA43/Main!$D$13 -> 8090.4051 | AB14: =AB43/Main!$D$13 -> 7921.2703 | AF14: =AF43/Main!$D$13 -> 14174.743 | AG14: =AG43/Main!$D$13 -> 16931.117 | AH14: =AH43/Main!$D$13 -> 14766.848 | AI14: =AI43/Main!$D$13 -> 18045.765 | AJ14: =AJ43/Main!$D$13 -> 18946.534 | AK14: =AK43/Main!$D$13 -> 25783.621 | AL14: =AL43/Main!$D$13 -> 23717.342 | AM14: =AM43/Main!$D$13 -> 45002.811 | AN14: =AN43/Main!$D$13 -> 41445.946 | AO14: =AO7-AO13 -> 34025.789 | AP14: =AP7-AP13 -> 35021.488 | AQ14: =AQ7-AQ13 -> 38805.916 | AR14: =AR7-AR13 -> 42663.619 | AS14: =AS7-AS13 -> 43203.486 | AT14: =AT7-AT13 -> 43751.015 | AU14: =AU7-AU13 -> 44306.33 | AV14: =AV7-AV13 -> 44869.554 | ... AX14: =AX7-AX13 -> 46020.236
B15: Taxes | C15: =C44/Main!$D$13 -> 1418.899 | D15: =D44/Main!$D$13 -> 1409.989 | E15: =E44/Main!$D$13 -> 1200.1551 | F15: =F44/Main!$D$13 -> 376.31324 | G15: =G44/Main!$D$13 -> -201.67991 | H15: =H44/Main!$D$13 -> 832.46753 | I15: =I44/Main!$D$13 -> 1768.2109 | J15: =J14*0.24 -> 1132.5278 | W15: =W44/Main!$D$13 -> 3285.1005 | X15: =X44/Main!$D$13 -> 2312.9999 | AA15: =AA44/Main!$D$13 -> 2454.9913 | AB15: =AB44/Main!$D$13 -> 1634.9034 | AF15: =AF44/Main!$D$13 -> 4063.449 | AG15: =AG44/Main!$D$13 -> 3259.0683 | AH15: =AH44/Main!$D$13 -> 4264.0305 | AI15: =AI44/Main!$D$13 -> 4405.3563 | AJ15: =AJ44/Main!$D$13 -> 4199.6253 | AK15: =AK44/Main!$D$13 -> 7210.1699 | AL15: =AL44/Main!$D$13 -> 7596.8534 | AM15: =AM44/Main!$D$13 -> 12235.349 | AN15: =AN44/Main!$D$13 -> 10498.385 | AO15: =AO14*0.26 -> 8846.705 | AP15: =AP14*0.26 -> 9105.5869 | AQ15: =AQ14*0.26 -> 10089.538 | AR15: =AR14*0.26 -> 11092.541 | AS15: =AS14*0.26 -> 11232.906 | AT15: =AT14*0.26 -> 11375.264 | AU15: =AU14*0.26 -> 11519.646 | AV15: =AV14*0.26 -> 11666.084 | ... AX15: =AX14*0.26 -> 11965.261
B16: Minority interest | C16: =C45/Main!$D$13 -> 79.162628 | D16: =D45/Main!$D$13 -> 143.44511 | E16: =E45/Main!$D$13 -> 173.76753 | F16: =F45/Main!$D$13 -> 88.117852 | G16: =G45/Main!$D$13 -> -60.70944 | H16: =H45/Main!$D$13 -> 72.468825 | I16: =I45/Main!$D$13 -> 186.16011 | J16: 300 | W16: =W45/Main!$D$13 -> 196.91155 | X16: =X45/Main!$D$13 -> -464.80584 | AA16: =AA45/Main!$D$13 -> 199.31511 | AB16: =AB45/Main!$D$13 -> 264.01111 | AF16: =AF45/Main!$D$13 -> -1719.8682 | AG16: =AG45/Main!$D$13 -> -2442.0753 | AH16: =AH45/Main!$D$13 -> -1662.8029 | AI16: =AI45/Main!$D$13 -> 484.49312 | AJ16: =AJ45/Main!$D$13 -> 239.82684 | AK16: =AK45/Main!$D$13 -> 158.32526 | AL16: =AL45/Main!$D$13 -> 269.109 | AM16: =AM45/Main!$D$13 -> 817.26433 | AN16: =AN45/Main!$D$13 -> 159.39782 | AO16: =AN16*1.01 -> 160.99179 | AP16: =AO16*1.01 -> 162.60171 | AQ16: =AP16*1.01 -> 164.22773 | AR16: =AQ16*1.01 -> 165.87001 | AS16: =AR16*1.01 -> 167.52871 | AT16: =AS16*1.01 -> 169.20399 | AU16: =AT16*1.01 -> 170.89603 | AV16: =AU16*1.01 -> 172.60499 | ... AX16: =AW16*1.01 -> 176.07435
B17: Net income | C17: =C46/Main!$D$13 -> 4000.3166 | D17: =D46/Main!$D$13 -> 3427.0854 | E17: =E46/Main!$D$13 -> 3613.7494 | F17: =F46/Main!$D$13 -> 2114.7638 | G17: =G46/Main!$D$13 -> 1026.3229 | H17: =H46/Main!$D$13 -> 3040.1564 | I17: =I46/Main!$D$13 -> 5418.9765 | J17: =J14-J15-J16 -> 3286.338 | W17: =W46/Main!$D$13 -> 8617.9298 | X17: =X46/Main!$D$13 -> 3704.3096 | AA17: =AA46/Main!$D$13 -> 5436.0987 | AB17: =AB46/Main!$D$13 -> 6022.3558 | AF17: =AF46/Main!$D$13 -> 11831.162 | AG17: =AG46/Main!$D$13 -> 16114.124 | AH17: =AH46/Main!$D$13 -> 12165.62 | AI17: =AI46/Main!$D$13 -> 13155.915 | AJ17: =AJ46/Main!$D$13 -> 14507.081 | AK17: =AK46/Main!$D$13 -> 18415.126 | AL17: =AL46/Main!$D$13 -> 15851.379 | AM17: =AM46/Main!$D$13 -> 31950.197 | AN17: =AN46/Main!$D$13 -> 30788.163 | AO17: =AO14-AO15-AO16 -> 25018.092 | AP17: =AP14-AP15-AP16 -> 25753.3 | AQ17: =AQ14-AQ15-AQ16 -> 28552.15 | AR17: =AR14-AR15-AR16 -> 31405.208 | AS17: =AS14-AS15-AS16 -> 31803.051 | AT17: =AT14-AT15-AT16 -> 32206.547 | AU17: =AU14-AU15-AU16 -> 32615.788 | AV17: =AV14-AV15-AV16 -> 33030.865 | ... AX17: =AX14-AX15-AX16 -> 33878.9 | AY17: =AX17*(1+$BA$23) -> 33540.111 | AZ17: =AY17*(1+$BA$23) -> 33204.71 | BA17: =AZ17*(1+$BA$23) -> 32872.663 | BB17: =BA17*(1+$BA$23) -> 32543.937 | BC17: =BB17*(1+$BA$23) -> 32218.497 | BD17: =BC17*(1+$BA$23) -> 31896.312 | BE17: =BD17*(1+$BA$23) -> 31577.349 | BF17: =BE17*(1+$BA$23) -> 31261.576 | ... EI17: =EH17*(1+$BA$23) -> 13850.378
B18: Shares | C18: =C47/Main!$D$13 -> 19.041158 | D18: =D47/Main!$D$13 -> 19.041158 | E18: =E47/2 -> 1473.5 | F18: =F47/2 -> 1473.5 | G18: =G47/2 -> 1473.5 | H18: =H47/2 -> 1473.5 | I18: =I47/2 -> 1631.5 | J18: 1632 | W18: =(15795-2762)/10 -> 1303.3 | X18: =(15795-2762)/10 -> 1303.3 | AA18: =(15795-2762)/10 -> 1303.3 | AB18: =(15795-2762)/10 -> 1303.3 | AF18: =AF47/2 -> 1473.5 | AG18: =AG47/2 -> 1473.5 | AH18: =AH47/2 -> 1435.5 | AI18: =AI47/2 -> 1415.5 | AJ18: =AJ47/2 -> 1415.5 | AK18: =AK47/2 -> 1415.5 | AL18: =AL47/2 -> 1415.5 | AM18: =AM47/2 -> 1415.5 | AN18: =AN47/2 -> 1415.5 | AO18: =(15795-2762)/10 -> 1303.3 | AP18: =(15795-2762)/10 -> 1303.3 | AQ18: =(15795-2762)/10 -> 1303.3 | AR18: =(15795-2762)/10 -> 1303.3 | AS18: =(15795-2762)/10 -> 1303.3 | AT18: =(15795-2762)/10 -> 1303.3 | AU18: =(15795-2762)/10 -> 1303.3 | AV18: =(15795-2762)/10 -> 1303.3 | ... AX18: =(15795-2762)/10 -> 1303.3
B19: EPS | C19: =C48/Main!$D$13 -> 1.35742 | D19: =D48/Main!$D$13 -> 1.1629065 | E19: =E48/Main!$D$13 -> 1.2262468 | F19: =F48/Main!$D$13 -> 0.71759886 | G19: =G48/Main!$D$13 -> 0.34826024 | H19: =H48/Main!$D$13 -> 1.0316106 | I19: =I48/Main!$D$13 -> 1.6607345 | J19: =J17/J18 -> 2.0136875 | W19: =W17/W18 -> 6.6123915 | X19: =X17/X18 -> 2.842254 | AA19: =AA17/AA18 -> 4.1710264 | AB19: =AB17/AB18 -> 4.6208515 | AF19: =AF48/Main!$D$13 -> 4.0146462 | AG19: =AG17/AG18 -> 10.935951 | AH19: =AH17/AH18 -> 8.474831 | AI19: =AI17/AI18 -> 9.2941824 | AJ19: =AJ17/AJ18 -> 10.248733 | AK19: =AK17/AK18 -> 13.009626 | AL19: =AL17/AL18 -> 11.198431 | AM19: =AM17/AM18 -> 22.571669 | AN19: =AN17/AN18 -> 21.750733 | ... AX19: =AX17/AX18 -> 25.994706
B21: Revenue y/y | G21: =G3/C3-1 -> -0.40414022 | H21: =H3/D3-1 -> -0.11294704 | I21: =I3/E3-1 -> 0.071113932 | J21: =J3/F3-1 -> 0.15 | AA21: =AA3/W3-1 -> 0.035094716 | AB21: =AB3/X3-1 -> 0.081510788 | AG21: =AG3/AF3-1 -> 0.064583271 | AH21: =AH3/AG3-1 -> 0.028801399 | AI21: =AI3/AH3-1 -> -0.01188175 | AJ21: =AJ3/AI3-1 -> -0.088793425 | AK21: =AK3/AJ3-1 -> 0.15303969 | AL21: =AL3/AK3-1 -> 0.18403065 | AM21: =AM3/AL3-1 -> 0.21373105 | AN21: =AN3/AM3-1 -> 0.065225808 | ... AX21: =AX3/AW3-1 -> 0.01
B22: Gross Margin | C22: =C5/C3 -> 0.18806847 | D22: =D5/D3 -> 0.17697935 | E22: =E5/E3 -> 0.18165167 | F22: =F5/F3 -> 0.17324863 | G22: =G5/G3 -> 0.1194202 | H22: =H5/H3 -> 0.16948253 | I22: =I5/I3 -> 0.20327552 | J22: =J5/J3 -> 0.18 | W22: =W5/W3 -> 0.20517991 | X22: =X5/X3 -> 0.21303035 | AA22: =AA5/AA3 -> 0.17920139 | AB22: =AB5/AB3 -> 0.15906682 | AF22: =AF5/AF3 -> 0.17620839 | AG22: =AG5/AG3 -> 0.18687708 | AH22: =AH5/AH3 -> 0.1801083 | AI22: =AI5/AI3 -> 0.1801747 | AJ22: =AJ5/AJ3 -> 0.17756554 | AK22: =AK5/AK3 -> 0.19030487 | AL22: =AL5/AL3 -> 0.16991348 | AM22: =AM5/AM3 -> 0.20774477 | ... AX22: =AX5/AX3 -> 0.19
B23: Operating Margin | C23: =C7/C3 -> 0.095918251 | D23: =D7/D3 -> 0.086238923 | E23: =E7/E3 -> 0.084124432 | F23: =F7/F3 -> 0.052166737 | G23: =G7/G3 -> 0.0030255634 | H23: =H7/H3 -> 0.074701668 | I23: =I7/I3 -> 0.12121916 | J23: =J7/J3 -> 0.083134489 | W23: =W7/W3 -> 0.11056972 | X23: =X7/X3 -> 0.10094795 | AA23: =AA7/AA3 -> 0.095169344 | AB23: =AB7/AB3 -> 0.067829202 | AF23: =AF7/AF3 -> 0.072267205 | AG23: =AG7/AG3 -> 0.081684889 | AH23: =AH7/AH3 -> 0.081637367 | AI23: =AI7/AI3 -> 0.080331717 | AJ23: =AJ7/AJ3 -> 0.080756266 | AK23: =AK7/AK3 -> 0.095466637 | AL23: =AL7/AL3 -> 0.073343493 | AM23: =AM7/AM3 -> 0.11870266 | ... AX23: =AX7/AX3 -> 0.093313586 | AZ23: Maturity | BA23: -0.01
B24: SG&A y/y | G24: =G6/C6-1 -> -0.24737146 | H24: =H6/D6-1 -> -0.07344892 | I24: =I6/E6-1 -> -0.09879824 | J24: =J6/F6-1 -> -0.08 | AA24: =AA6/W6-1 -> -0.080636866 | AB24: =AB6/X6-1 -> -0.11962564 | AG24: =AG6/AF6-1 -> 0.077396256 | AH24: =AH6/AG6-1 -> -0.036933889 | AI24: =AI6/AH6-1 -> 0.0018862023 | AJ24: =AJ6/AI6-1 -> -0.11648024 | AK24: =AK6/AJ6-1 -> 0.12956379 | AL24: =AL6/AK6-1 -> 0.20565112 | AM24: =AM6/AL6-1 -> 0.11911767 | AN24: =AN6/AM6-1 -> 0.19103259 | ... AX24: =AX6/AW6-1 -> 0.01 | AZ24: Discount rate | BA24: 0.05
B25: Taxes | C25: =C15/C14 -> 0.25805773 | D25: =D15/D14 -> 0.28310079 | E25: =E15/E14 -> 0.2406243 | F25: =F15/F14 -> 0.14590337 | G25: =G15/G14 -> -0.26400189 | H25: =H15/H14 -> 0.21101343 | I25: =I15/I14 -> 0.23981114 | J25: =J15/J14 -> 0.24 | W25: =W15/W14 -> 0.27149721 | X25: =X15/X14 -> 0.41656882 | AA25: =AA15/AA14 -> 0.30344479 | AB25: =AB15/AB14 -> 0.20639409 | AF25: =AF15/AF14 -> 0.28666826 | AG25: =AG15/AG14 -> 0.19248986 | AH25: =AH15/AH14 -> 0.28875699 | AI25: =AI15/AI14 -> 0.24412134 | AJ25: =AJ15/AJ14 -> 0.22165665 | AK25: =AK15/AK14 -> 0.27964148 | AL25: =AL15/AL14 -> 0.32030796 | AM25: =AM15/AM14 -> 0.27187967 | ... AX25: =AX15/AX14 -> 0.26 | AZ25: NPV | BA25: =NPV(BA24,AO17:EI17) -> 575890.86
B26: Net Margin | C26: =C17/C3 -> 0.080184835 | D26: =D17/D3 -> 0.069452628 | E26: =E17/E3 -> 0.073505726 | F26: =F17/F3 -> 0.047439617 | G26: =G17/G3 -> 0.03452533 | H26: =H17/H3 -> 0.069456059 | I26: =I17/I3 -> 0.10290696 | J26: =J17/J3 -> 0.064105263 | W26: =W17/W3 -> 0.11267196 | X26: =X17/X3 -> 0.050095019 | AA26: =AA17/AA3 -> 0.068662582 | AB26: =AB17/AB3 -> 0.075304827 | AF26: =AF17/AF3 -> 0.066351277 | AG26: =AG17/AG3 -> 0.084888516 | AH26: =AH17/AH3 -> 0.062293816 | AI26: =AI17/AI3 -> 0.068174637 | AJ26: =AJ17/AJ3 -> 0.082502094 | AK26: =AK17/AK3 -> 0.09082708 | AL26: =AL17/AL3 -> 0.06603053 | AM26: =AM17/AM3 -> 0.10965509 | ... AX26: =AX17/AX3 -> 0.095025111 | AZ26: Net cash | BA26: =Main!D10 -> -155149.09
AZ27: Value | BA27: =BA25+BA26 -> 420741.77
AZ28: Per share | BA28: =BA27/AX18 -> 322.82803
AZ29: Current price | BA29: =Main!D3 -> 199.06
AZ30: Variance | BA30: =BA28/BA29-1 -> 0.62176243
AZ31: Consensus | BA31: Heavily undervalued
B32: Revenue | C32: 7721273 | D32: 7637004 | E32: 7608931 | F32: =AI32-E32-D32-C32 -> 6899339 | G32: 4600796 | H32: 6774427 | I32: 8150032 | W32: 11837879 | X32: =X51-W32 -> 11444571 | AA32: 12253326 | AB32: =AB51-AA32 -> 12377427 | AF32: 27597193 | AG32: 29379510 | AH32: 30225681 | AI32: 29866547 | AJ32: 27214594 | AK32: 31379507 | AL32: 37154298 | AM32: 45095325 | AN32: 48036704
B33: Cost of sales | C33: =5927739+341406 -> 6269145 | D33: =5973620+311792 -> 6285412 | E33: =5866014+360742 -> 6226756 | F33: =AI33-E33-D33-C33 -> 5704038 | G33: =3726300+325068 -> 4051368 | H33: =5351939+274341 -> 5626280 | I33: =6211206+282124 -> 6493330 | W33: =8774492+634492 -> 9408984 | X33: =X52-W33 -> 9006530 | AA33: =9337703+719810 -> 10057513 | AB33: =AB52-AA33 -> 10408589 | AF33: =21543035+1191301 -> 22734336 | AG33: =22600474+1288679 -> 23889153 | AH33: =23389495+1392290 -> 24781785 | AI33: =23103596+1381755 -> 24485351 | AJ33: =21199890+1182330 -> 22382220 | AK33: =24250784+1157050 -> 25407834 | AL33: =29128561+1712721 -> 30841282 | AM33: =33600612+2126395 -> 35727007 | AN33: =35510157+2948509 -> 38458666
B34: Gross profit | C34: =C32-C33 -> 1452128 | D34: =D32-D33 -> 1351592 | E34: =E32-E33 -> 1382175 | F34: =F32-F33 -> 1195301 | G34: =G32-G33 -> 549428 | H34: =H32-H33 -> 1148147 | I34: =I32-I33 -> 1656702 | W34: =W32-W33 -> 2428895 | X34: =X32-X33 -> 2438041 | AA34: =AA32-AA33 -> 2195813 | AB34: =AB32-AB33 -> 1968838 | AF34: =AF32-AF33 -> 4862857 | AG34: =AG32-AG33 -> 5490357 | AH34: =AH32-AH33 -> 5443896 | AI34: =AI32-AI33 -> 5381196 | AJ34: =AJ32-AJ33 -> 4832374 | AK34: =AK32-AK33 -> 5971673 | AL34: =AL32-AL33 -> 6313016 | AM34: =AM32-AM33 -> 9368318 | AN34: =AN32-AN33 -> 9578038 | BB34: if they outperform earnings, could be a good target
B35: SG&A | C35: 711517 | D35: 692985 | E35: 742078 | F35: =AI35-E35-D35-C35 -> 835385 | G35: 535508 | H35: 642086 | I35: 668762 | W35: 1119984 | X35: =X54-W35 -> 1282735 | AA35: 1029672 | AB35: =AB54-AA35 -> 1129287 | AF35: 2868485 | AG35: 3090495 | AH35: 2976351 | AI35: 2981965 | AJ35: 2634625 | AK35: 2975977 | AL35: 3587990 | AM35: 4015383 | AN35: 4782452
B36: Operating profit | C36: =C34-C35 -> 740611 | D36: =D34-D35 -> 658607 | E36: =E34-E35 -> 640097 | F36: =F34-F35 -> 359916 | G36: =G34-G35 -> 13920 | H36: =H34-H35 -> 506061 | I36: =I34-I35 -> 987940 | W36: =W34-W35 -> 1308911 | X36: =X34-X35 -> 1155306 | AA36: =AA34-AA35 -> 1166141 | AB36: =AB34-AB35 -> 839551 | AF36: =AF34-AF35 -> 1994372 | AG36: =AG34-AG35 -> 2399862 | AH36: =AH34-AH35 -> 2467545 | AI36: =AI34-AI35 -> 2399231 | AJ36: =AJ34-AJ35 -> 2197749 | AK36: =AK34-AK35 -> 2995696 | AL36: =AL34-AL35 -> 2725026 | AM36: =AM34-AM35 -> 5352935 | AN36: =AN34-AN35 -> 4795586
B37: Investments | C37: -104744 | D37: -95122 | E37: -75836 | F37: =AI37-E37-D37-C37 -> -34545 | G37: 12572 | H37: -88962 | I37: -125084 | W37: -164937 | X37: =X56-W37 -> -99378 | AA37: -141044 | AB37: =AB56-AA37 -> -131580 | AI37: -310247 | AJ37: -351029 | AK37: -560346 | AL37: =-643063 -> -643063 | AM37: -763137 | AN37: -591219
B38: Other finance income | C38: -77551 | D38: -64152 | E38: -61093 | F38: =AI38-E38-D38-C38 -> -103050 | G38: -114789 | H38: -53185 | I38: -52879 | W38: -173800 | X38: =X57-W38 -> -97145 | AA38: -153721 | AB38: =AB57-AA38 -> -139025 | AI38: -305846 | AJ38: -435229 | AK38: -334760 | AL38: -379350 | AM38: -747236 | AN38: -556700
B39: Other finance costs | C39: 9842 | D39: 12707 | E39: 11851 | F39: =AI39-E39-D39-C39 -> 12755 | G39: 10012 | H39: 13225 | I39: 9859 | W39: 16509 | X39: =X58-W39 -> 37185 | AA39: 6211 | AB39: =AB58-AA39 -> 18799 | AI39: 47155 | AJ39: 47537 | AK39: 43997 | AL39: 123113 | AM39: 103709 | AN39: 190711
B40: Finance income | C40: 63060 | D40: 20252 | E40: -26326 | F40: =AI40-E40-D40-C40 -> 37633 | G40: -8510 | H40: 20695 | I40: 622 | W40: -236999 | X40: =X59-W40 -> 463810 | AA40: 212375 | AB40: =AB59-AA40 -> -159588 | AI40: 94619 | AJ40: -15142 | AK40: -216187 | AL40: -124516 | AM40: -187568 | AN40: -705292
B41: Other income | C41: -980 | D41: 14087 | E41: 19559 | F41: =AI41-E41-D41-C41 -> 47941 | G41: -3599 | H41: 3706 | I41: 14249 | W41: -4570 | X41: =X60-W41 -> -8527 | AA41: -9832 | AB41: =AB60-AA41 -> 24970 | AI41: 80607 | AJ41: 19257 | AK41: 72461 | AL41: 78109 | AM41: -17918 | AN41: 43497
...

Sheet Currency
A1: title | B1: link | C1: description | D1: pubDate | E1: baseCurrency | F1: baseName | G1: targetCurrency | H1: targetName | I1: exchangeRate | J1: inverseRate | K1: inverseDescription
A2: 1 USD = 106.31855806 JPY | B2: http://www.floatrates.com/usd/jpy/ | C2: 1 U.S. Dollar = 106.31855806 Japanese Yen | D2: 44256.125 | E2: USD | F2: U.S. Dollar | G2: JPY | H2: Japanese Yen | I2: 106.31856 | J2: 0.0094057 | K2: 1 Japanese Yen = 0.00940570 U.S. Dollar
